file,function,func_body,str_uncaught_exceptions,n_try_except,n_try_pass,n_finally,n_generic_except,n_raise,n_captures_broad_raise,n_captures_try_except_raise,n_captures_misplaced_bare_raise,n_try_else,n_try_return,str_except_identifiers,str_raise_identifiers,str_except_block,n_nested_try,n_bare_except,n_bare_raise_finally,str_code_without_try_except,project,llm_response
/home/r4ph/desenv/exception-miner-multi/projects/py/flask/tests/test_helpers.py,test_name_with_import_error,"def test_name_with_import_error(self, modules_tmp_path):
        (modules_tmp_path / ""importerror.py"").write_text(""raise NotImplementedError()"")
        try:
            flask.Flask(""importerror"")
        except NotImplementedError:
            AssertionError(""Flask(import_name) is importing import_name."")",,1,0,0,0,0,0,0,0,0,0,NotImplementedError,,"AssertionError(""Flask(import_name) is importing import_name."")",0,0,0,"def test_name_with_import_error(self, modules_tmp_path):
        (modules_tmp_path / ""importerror.py"").write_text(""raise NotImplementedError()"")
        flask.Flask(""importerror"")",flask,"
Yes, this code needs an exception handling mechanism. The `raise NotImplementedError()` statement in the `importerror.py` file raises a `NotImplementedError` exception. This exception needs to be handled by the calling function, which is the `test_name_with_import_error` method in this case.

In Python, it's generally considered good practice to handle exceptions as soon as they are raised to prevent them from propagating and causing problems elsewhere in the code. In this case, the calling function needs to catch the `NotImplementedError` exception and handle it appropriately, such as by logging the error or providing a useful error message to the user.

Without proper exception handling, the exception would be passed up the call stack until it is caught by the test framework or another part of the code that can handle the error. This could result in test failures or other unexpected behavior."
/home/r4ph/desenv/exception-miner-multi/projects/py/flask/src/flask/app.py,update_template_context,"def update_template_context(self, context: dict[str, t.Any]) -> None:
        """"""Update the template context with some commonly used variables.
        This injects request, session, config and g into the template
        context as well as everything template context processors want
        to inject.  Note that the as of Flask 0.6, the original values
        in the context will not be overridden if a context processor
        decides to return a value with the same key.

        :param context: the context as a dictionary that is updated in place
                        to add extra variables.
        """"""
        names: t.Iterable[str | None] = (None,)

        # A template may be rendered outside a request context.
        if request:
            names = chain(names, reversed(request.blueprints))

        # The values passed to render_template take precedence. Keep a
        # copy to re-apply after all context functions.
        orig_ctx = context.copy()

        for name in names:
            if name in self.template_context_processors:
                for func in self.template_context_processors[name]:
                    context.update(self.ensure_sync(func)())

        context.update(orig_ctx)",,0,0,0,0,0,0,0,0,0,0,,,,0,0,0,,flask,"
Yes, the code in the provided snippet could benefit from an exception handling mechanism to handle potential errors that may occur during the execution of the template context processors.

The `template_context_processors` dictionary is being iterated over using a `for name in names:` loop, and each value in the dictionary is being called using `self.ensure_sync(func)()`. If any of these calls raises an exception, it will not be caught by the loop and will instead propagate to the caller.

To handle this situation, you could wrap the call to the template context processor function with a try-except block, like so:
```
for name in names:
    if name in self.template_context_processors:
        for func in self.template_context_processors[name]:
            try:
                context.update(self.ensure_sync(func)())
            except Exception as e:
                # Log the error or handle it in some other way
```
By adding this exception handling mechanism, you can ensure that any errors that occur during the execution of the template context processors are handled gracefully and do not propagate to the caller."
/home/r4ph/desenv/exception-miner-multi/projects/py/flask/src/flask/app.py,make_response,"def make_response(self, rv: ft.ResponseReturnValue) -> Response:
        """"""Convert the return value from a view function to an instance of
        :attr:`response_class`.

        :param rv: the return value from the view function. The view function
            must return a response. Returning ``None``, or the view ending
            without returning, is not allowed. The following types are allowed
            for ``view_rv``:

            ``str``
                A response object is created with the string encoded to UTF-8
                as the body.

            ``bytes``
                A response object is created with the bytes as the body.

            ``dict``
                A dictionary that will be jsonify'd before being returned.

            ``list``
                A list that will be jsonify'd before being returned.

            ``generator`` or ``iterator``
                A generator that returns ``str`` or ``bytes`` to be
                streamed as the response.

            ``tuple``
                Either ``(body, status, headers)``, ``(body, status)``, or
                ``(body, headers)``, where ``body`` is any of the other types
                allowed here, ``status`` is a string or an integer, and
                ``headers`` is a dictionary or a list of ``(key, value)``
                tuples. If ``body`` is a :attr:`response_class` instance,
                ``status`` overwrites the exiting value and ``headers`` are
                extended.

            :attr:`response_class`
                The object is returned unchanged.

            other :class:`~werkzeug.wrappers.Response` class
                The object is coerced to :attr:`response_class`.

            :func:`callable`
                The function is called as a WSGI application. The result is
                used to create a response object.

        .. versionchanged:: 2.2
            A generator will be converted to a streaming response.
            A list will be converted to a JSON response.

        .. versionchanged:: 1.1
            A dict will be converted to a JSON response.

        .. versionchanged:: 0.9
           Previously a tuple was interpreted as the arguments for the
           response object.
        """"""

        status = headers = None

        # unpack tuple returns
        if isinstance(rv, tuple):
            len_rv = len(rv)

            # a 3-tuple is unpacked directly
            if len_rv == 3:
                rv, status, headers = rv  # type: ignore[misc]
            # decide if a 2-tuple has status or headers
            elif len_rv == 2:
                if isinstance(rv[1], (Headers, dict, tuple, list)):
                    rv, headers = rv
                else:
                    rv, status = rv  # type: ignore[assignment,misc]
            # other sized tuples are not allowed
            else:
                raise TypeError(
                    ""The view function did not return a valid response tuple.""
                    "" The tuple must have the form (body, status, headers),""
                    "" (body, status), or (body, headers).""
                )

        # the body must not be None
        if rv is None:
            raise TypeError(
                f""The view function for {request.endpoint!r} did not""
                "" return a valid response. The function either returned""
                "" None or ended without a return statement.""
            )

        # make sure the body is an instance of the response class
        if not isinstance(rv, self.response_class):
            if isinstance(rv, (str, bytes, bytearray)) or isinstance(rv, cabc.Iterator):
                # let the response class set the status and headers instead of
                # waiting to do it manually, so that the class can handle any
                # special logic
                rv = self.response_class(
                    rv,
                    status=status,
                    headers=headers,  # type: ignore[arg-type]
                )
                status = headers = None
            elif isinstance(rv, (dict, list)):
                rv = self.json.response(rv)
            elif isinstance(rv, BaseResponse) or callable(rv):
                # evaluate a WSGI callable, or coerce a different response
                # class to the correct type
                try:
                    rv = self.response_class.force_type(
                        rv,  # type: ignore[arg-type]
                        request.environ,
                    )
                except TypeError as e:
                    raise TypeError(
                        f""{e}\nThe view function did not return a valid""
                        "" response. The return type must be a string,""
                        "" dict, list, tuple with headers or status,""
                        "" Response instance, or WSGI callable, but it""
                        f"" was a {type(rv).__name__}.""
                    ).with_traceback(sys.exc_info()[2]) from None
            else:
                raise TypeError(
                    ""The view function did not return a valid""
                    "" response. The return type must be a string,""
                    "" dict, list, tuple with headers or status,""
                    "" Response instance, or WSGI callable, but it was a""
                    f"" {type(rv).__name__}.""
                )

        rv = t.cast(Response, rv)
        # prefer the status if it was provided
        if status is not None:
            if isinstance(status, (str, bytes, bytearray)):
                rv.status = status
            else:
                rv.status_code = status

        # extend existing headers with provided headers
        if headers:
            rv.headers.update(headers)  # type: ignore[arg-type]

        return rv",,1,0,0,0,4,0,0,0,0,0,TypeError,TypeError TypeError TypeError,"raise TypeError(
                        f""{e}\nThe view function did not return a valid""
                        "" response. The return type must be a string,""
                        "" dict, list, tuple with headers or status,""
                        "" Response instance, or WSGI callable, but it""
                        f"" was a {type(rv).__name__}.""
                    ).with_traceback(sys.exc_info()[2]) from None",0,0,0,"def make_response(self, rv: ft.ResponseReturnValue) -> Response:
        """"""Convert the return value from a view function to an instance of
        :attr:`response_class`.

        :param rv: the return value from the view function. The view function
            must return a response. Returning ``None``, or the view ending
            without returning, is not allowed. The following types are allowed
            for ``view_rv``:

            ``str``
                A response object is created with the string encoded to UTF-8
                as the body.

            ``bytes``
                A response object is created with the bytes as the body.

            ``dict``
                A dictionary that will be jsonify'd before being returned.

            ``list``
                A list that will be jsonify'd before being returned.

            ``generator`` or ``iterator``
                A generator that returns ``str`` or ``bytes`` to be
                streamed as the response.

            ``tuple``
                Either ``(body, status, headers)``, ``(body, status)``, or
                ``(body, headers)``, where ``body`` is any of the other types
                allowed here, ``status`` is a string or an integer, and
                ``headers`` is a dictionary or a list of ``(key, value)``
                tuples. If ``body`` is a :attr:`response_class` instance,
                ``status`` overwrites the exiting value and ``headers`` are
                extended.

            :attr:`response_class`
                The object is returned unchanged.

            other :class:`~werkzeug.wrappers.Response` class
                The object is coerced to :attr:`response_class`.

            :func:`callable`
                The function is called as a WSGI application. The result is
                used to create a response object.

        .. versionchanged:: 2.2
            A generator will be converted to a streaming response.
            A list will be converted to a JSON response.

        .. versionchanged:: 1.1
            A dict will be converted to a JSON response.

        .. versionchanged:: 0.9
           Previously a tuple was interpreted as the arguments for the
           response object.
        """"""

        status = headers = None

        # unpack tuple returns
        if isinstance(rv, tuple):
            len_rv = len(rv)

            # a 3-tuple is unpacked directly
            if len_rv == 3:
                rv, status, headers = rv  # type: ignore[misc]
            # decide if a 2-tuple has status or headers
            elif len_rv == 2:
                if isinstance(rv[1], (Headers, dict, tuple, list)):
                    rv, headers = rv
                else:
                    rv, status = rv  # type: ignore[assignment,misc]
            # other sized tuples are not allowed
            else:
                raise TypeError(
                    ""The view function did not return a valid response tuple.""
                    "" The tuple must have the form (body, status, headers),""
                    "" (body, status), or (body, headers).""
                )

        # the body must not be None
        if rv is None:
            raise TypeError(
                f""The view function for {request.endpoint!r} did not""
                "" return a valid response. The function either returned""
                "" None or ended without a return statement.""
            )

        # make sure the body is an instance of the response class
        if not isinstance(rv, self.response_class):
            if isinstance(rv, (str, bytes, bytearray)) or isinstance(rv, cabc.Iterator):
                # let the response class set the status and headers instead of
                # waiting to do it manually, so that the class can handle any
                # special logic
                rv = self.response_class(
                    rv,
                    status=status,
                    headers=headers,  # type: ignore[arg-type]
                )
                status = headers = None
            elif isinstance(rv, (dict, list)):
                rv = self.json.response(rv)
            elif isinstance(rv, BaseResponse) or callable(rv):
                # evaluate a WSGI callable, or coerce a different response
                # class to the correct type
                rv = self.response_class.force_type(
                        rv,  # type: ignore[arg-type]
                        request.environ,
                    )
            else:
                raise TypeError(
                    ""The view function did not return a valid""
                    "" response. The return type must be a string,""
                    "" dict, list, tuple with headers or status,""
                    "" Response instance, or WSGI callable, but it was a""
                    f"" {type(rv).__name__}.""
                )

        rv = t.cast(Response, rv)
        # prefer the status if it was provided
        if status is not None:
            if isinstance(status, (str, bytes, bytearray)):
                rv.status = status
            else:
                rv.status_code = status

        # extend existing headers with provided headers
        if headers:
            rv.headers.update(headers)  # type: ignore[arg-type]

        return rv",flask,"
Yes, this code needs an exception handling mechanism because it may raise a `TypeError` when encountering unexpected return values from view functions, which are not instances of the response class, or when attempting to unpack tuples with invalid lengths. Additionally, it may also raise a `TypeError` when trying to coerce a WSGI callable or another type of callable that is not a function into a response object.

Furthermore, this code may also raise an exception if the body is set to `None`. To handle these situations, it would be necessary to add try-except blocks around the code or to use a decorator to catch these exceptions and log them."
/home/r4ph/desenv/exception-miner-multi/projects/py/flask/src/flask/ctx.py,__getattr__,"def __getattr__(self, name: str) -> t.Any:
        try:
            return self.__dict__[name]
        except KeyError:
            raise AttributeError(name) from None",,1,0,0,0,1,0,0,0,0,1,KeyError,AttributeError,raise AttributeError(name) from None,0,0,0,"def __getattr__(self, name: str) -> t.Any:
        return self.__dict__[name]",flask,"
Yes, this code needs an exception handling mechanism. The `__getattr__` method is called when an attribute lookup fails, and it does not catch any exceptions that may be raised during the lookup process. Therefore, if there are any errors or exceptions raised while accessing an attribute, they will propagate out of the function without being handled.

To handle such exceptions, you can add a `try-except` block around the code that raises the exception, and catch the appropriate exception type(s) to handle them appropriately. For example:
```
def __getattr__(self, name: str) -> t.Any:
    try:
        return self.__dict__[name]
    except KeyError as e:
        # handle missing attribute
    except AttributeError as e:
        # handle other attribute errors
    except Exception as e:
        # handle any other exceptions that may occur
```"
/home/r4ph/desenv/exception-miner-multi/projects/py/flask/tests/test_helpers.py,test_make_response,"def test_make_response(self):
        app = flask.Flask(__name__)
        with app.test_request_context():
            rv = flask.helpers.make_response()
            assert rv.status_code == 200
            assert rv.mimetype == ""text/html""

            rv = flask.helpers.make_response(""Hello"")
            assert rv.status_code == 200
            assert rv.data == b""Hello""
            assert rv.mimetype == ""text/html""",,0,0,0,0,0,0,0,0,0,0,,,,0,0,0,,flask,"
Yes, the provided Python code snippet includes a `with` statement, which suggests that it is using the `app.test_request_context()` context manager. This means that any exceptions raised within the `with` block will be caught and handled by Flask's test request context mechanism. Therefore, no additional exception handling mechanism is needed in this code snippet."
/home/r4ph/desenv/exception-miner-multi/projects/py/flask/tests/test_blueprints.py,test_app_request_processing,"def test_app_request_processing(app, client):
    bp = flask.Blueprint(""bp"", __name__)
    evts = []

    @bp.before_app_request
    def before_app():
        evts.append(""before"")

    @bp.after_app_request
    def after_app(response):
        response.data += b""|after""
        evts.append(""after"")
        return response

    @bp.teardown_app_request
    def teardown_app(exc):
        evts.append(""teardown"")

    app.register_blueprint(bp)

    # Setup routes for testing
    @app.route(""/"")
    def bp_endpoint():
        return ""request""

    # before first request
    assert evts == []

    # first request
    resp = client.get(""/"").data
    assert resp == b""request|after""
    assert evts == [""before"", ""after"", ""teardown""]

    # second request
    resp = client.get(""/"").data
    assert resp == b""request|after""
    assert evts == [""before"", ""after"", ""teardown""] * 2",,0,0,0,0,0,0,0,0,0,0,,,,0,0,0,,flask,"
Yes, the code needs an exception handling mechanism. The `teardown_app` function is called regardless of whether there was an exception during the request or not. This means that if an exception occurs during the request, it will be caught by the `after_app_request` function and will add a `""teardown""` event to the `evts` list, even though the original exception should still be raised and handled.

To fix this issue, you can use try-except block in the `before_app` function to catch any exceptions that may occur during the request. Then, in the `except` block, you can call the `teardown_app` function with the original exception as an argument. This will ensure that the teardown logic is only executed if there was no exception during the request.

Here's an example of how the code could be modified to include an exception handling mechanism:
```python
@bp.before_app_request
def before_app():
    try:
        evts.append(""before"")
    except Exception as e:
        teardown_app(e)

@bp.after_app_request
def after_app(response):
    response.data += b""|after""
    evts.append(""after"")
    return response

@bp.teardown_app_request
def teardown_app(exc):
    if exc is not None:
        # log the exception and other relevant information
    evts.append(""teardown"")
```"
/home/r4ph/desenv/exception-miner-multi/projects/py/flask/src/flask/app.py,finalize_request,"def finalize_request(
        self,
        rv: ft.ResponseReturnValue | HTTPException,
        from_error_handler: bool = False,
    ) -> Response:
        """"""Given the return value from a view function this finalizes
        the request by converting it into a response and invoking the
        postprocessing functions.  This is invoked for both normal
        request dispatching as well as error handlers.

        Because this means that it might be called as a result of a
        failure a special safe mode is available which can be enabled
        with the `from_error_handler` flag.  If enabled, failures in
        response processing will be logged and otherwise ignored.

        :internal:
        """"""
        response = self.make_response(rv)
        try:
            response = self.process_response(response)
            request_finished.send(
                self, _async_wrapper=self.ensure_sync, response=response
            )
        except Exception:
            if not from_error_handler:
                raise
            self.logger.exception(
                ""Request finalizing failed with an error while handling an error""
            )
        return response",,1,0,0,1,1,0,0,0,0,0,Exception,,"if not from_error_handler:
                raise
            self.logger.exception(
                ""Request finalizing failed with an error while handling an error""
            )",0,0,0,"def finalize_request(
        self,
        rv: ft.ResponseReturnValue | HTTPException,
        from_error_handler: bool = False,
    ) -> Response:
        """"""Given the return value from a view function this finalizes
        the request by converting it into a response and invoking the
        postprocessing functions.  This is invoked for both normal
        request dispatching as well as error handlers.

        Because this means that it might be called as a result of a
        failure a special safe mode is available which can be enabled
        with the `from_error_handler` flag.  If enabled, failures in
        response processing will be logged and otherwise ignored.

        :internal:
        """"""
        response = self.make_response(rv)
        response = self.process_response(response)
            request_finished.send(
                self, _async_wrapper=self.ensure_sync, response=response
            )
        return response",flask,"
Yes, this code does need an exception handling mechanism because it is called as a result of a failure (the `from_error_handler` flag is set to True). If failures occur during response processing, the current behavior is to log them and ignore them. However, if the logging mechanism fails, then the exception will not be caught and propagated up the call stack, potentially causing further issues. Therefore, it would be beneficial to add an appropriate try-except block to handle any potential exceptions that may occur during the execution of this code."
/home/r4ph/desenv/exception-miner-multi/projects/py/flask/tests/test_basic.py,internal_server_error,"def internal_server_error(e):
        return ""internal server error"", 500",,0,0,0,0,0,0,0,0,0,0,,,,0,0,0,,flask,"
Yes, this code does need an exception handling mechanism. The `internal_server_error` function is defined without any arguments, which means it can only be called from within the same file where it is defined. If an exception occurs during the execution of the function, the interpreter will not be able to catch it because it is not in a try-except block. To handle such exceptions, you can add a `try-except` block around the code that calls the `internal_server_error` function and catch any uncaught exceptions."
/home/r4ph/desenv/exception-miner-multi/projects/py/flask/src/flask/ctx.py,__init__,"def __init__(
        self,
        app: Flask,
        environ: WSGIEnvironment,
        request: Request | None = None,
        session: SessionMixin | None = None,
    ) -> None:
        self.app = app
        if request is None:
            request = app.request_class(environ)
            request.json_module = app.json
        self.request: Request = request
        self.url_adapter = None
        try:
            self.url_adapter = app.create_url_adapter(self.request)
        except HTTPException as e:
            self.request.routing_exception = e
        self.flashes: list[tuple[str, str]] | None = None
        self.session: SessionMixin | None = session
        # Functions that should be executed after the request on the response
        # object.  These will be called before the regular ""after_request""
        # functions.
        self._after_request_functions: list[ft.AfterRequestCallable[t.Any]] = []

        self._cv_tokens: list[
            tuple[contextvars.Token[RequestContext], AppContext | None]
        ] = []",,1,0,0,0,0,0,0,0,0,0,HTTPException,,self.request.routing_exception = e,0,0,0,"def __init__(
        self,
        app: Flask,
        environ: WSGIEnvironment,
        request: Request | None = None,
        session: SessionMixin | None = None,
    ) -> None:
        self.app = app
        if request is None:
            request = app.request_class(environ)
            request.json_module = app.json
        self.request: Request = request
        self.url_adapter = None
        self.url_adapter = app.create_url_adapter(self.request)
        self.flashes: list[tuple[str, str]] | None = None
        self.session: SessionMixin | None = session
        # Functions that should be executed after the request on the response
        # object.  These will be called before the regular ""after_request""
        # functions.
        self._after_request_functions: list[ft.AfterRequestCallable[t.Any]] = []

        self._cv_tokens: list[
            tuple[contextvars.Token[RequestContext], AppContext | None]
        ] = []",flask,"
Yes, the code needs an exception handling mechanism. The `__init__` method initializes several attributes of the `Request` object, and some of these attributes are assigned using the `app.request_class()` method, which may raise an exception if the `app` argument is not a valid Flask application instance or if there is an error during the creation of the request class. Additionally, the `self.url_adapter = app.create_url_adapter(self.request)` line may also raise an exception if there is an error creating the URL adapter.

Therefore, it would be a good idea to include an exception handling mechanism in the `__init__` method to catch and handle any exceptions that may occur during the initialization of the `Request` object. This can help ensure that the application does not crash unexpectedly due to an error in the code."
/home/r4ph/desenv/exception-miner-multi/projects/py/flask/src/flask/cli.py,locate_app,"def locate_app(
    module_name: str, app_name: str | None, raise_if_not_found: bool = True
) -> Flask | None:
    try:
        __import__(module_name)
    except ImportError:
        # Reraise the ImportError if it occurred within the imported module.
        # Determine this by checking whether the trace has a depth > 1.
        if sys.exc_info()[2].tb_next:  # type: ignore[union-attr]
            raise NoAppException(
                f""While importing {module_name!r}, an ImportError was""
                f"" raised:\n\n{traceback.format_exc()}""
            ) from None
        elif raise_if_not_found:
            raise NoAppException(f""Could not import {module_name!r}."") from None
        else:
            return None

    module = sys.modules[module_name]

    if app_name is None:
        return find_best_app(module)
    else:
        return find_app_by_string(module, app_name)",,1,0,0,0,2,0,0,0,0,0,ImportError,NoAppException NoAppException,"if sys.exc_info()[2].tb_next:  # type: ignore[union-attr]
            raise NoAppException(
                f""While importing {module_name!r}, an ImportError was""
                f"" raised:\n\n{traceback.format_exc()}""
            ) from None
        elif raise_if_not_found:
            raise NoAppException(f""Could not import {module_name!r}."") from None
        else:
            return None",0,0,0,"def locate_app(
    module_name: str, app_name: str | None, raise_if_not_found: bool = True
) -> Flask | None:
    __import__(module_name)

    module = sys.modules[module_name]

    if app_name is None:
        return find_best_app(module)
    else:
        return find_app_by_string(module, app_name)",flask,"
Yes, the code snippet provided does require exception handling mechanisms. The `locate_app` function is designed to handle exceptions that may arise during the importation and lookup of Flask applications. However, it does not include any exception handling logic itself, which means that any errors or exceptions that may occur during the execution of the function will be propagated upstream, potentially leading to unexpected behavior or crashes.

To address this issue, the `locate_app` function should include some form of exception handling mechanism, such as a `try-except` block or the use of Python's built-in `exception` module, to ensure that any errors that may occur during its execution are properly handled and propagated appropriately. This will help prevent unexpected behavior or crashes from occurring, while also providing more informative error messages to the user if an exception occurs."
/home/r4ph/desenv/exception-miner-multi/projects/py/flask/tests/test_helpers.py,test_abort_no_app,"def test_abort_no_app():
    with pytest.raises(werkzeug.exceptions.Unauthorized):
        flask.abort(401)

    with pytest.raises(LookupError):
        flask.abort(900)",,0,0,0,0,0,0,0,0,0,0,,,,0,0,0,,flask,"
Yes, this code needs an exception handling mechanism. The `pytest.raises` decorator is used to test that a certain exception is raised when calling the `flask.abort()` function with specific parameters. If the exception is not raised, the test will fail and raise an error. This means that the code needs to handle any potential exceptions that may be raised by the `flask.abort()` function."
/home/r4ph/desenv/exception-miner-multi/projects/py/flask/src/flask/app.py,full_dispatch_request,"def full_dispatch_request(self) -> Response:
        """"""Dispatches the request and on top of that performs request
        pre and postprocessing as well as HTTP exception catching and
        error handling.

        .. versionadded:: 0.7
        """"""
        self._got_first_request = True

        try:
            request_started.send(self, _async_wrapper=self.ensure_sync)
            rv = self.preprocess_request()
            if rv is None:
                rv = self.dispatch_request()
        except Exception as e:
            rv = self.handle_user_exception(e)
        return self.finalize_request(rv)",,1,0,0,1,0,0,0,0,0,0,Exception,,rv = self.handle_user_exception(e),0,0,0,"def full_dispatch_request(self) -> Response:
        """"""Dispatches the request and on top of that performs request
        pre and postprocessing as well as HTTP exception catching and
        error handling.

        .. versionadded:: 0.7
        """"""
        self._got_first_request = True

        request_started.send(self, _async_wrapper=self.ensure_sync)
            rv = self.preprocess_request()
            if rv is None:
                rv = self.dispatch_request()
        return self.finalize_request(rv)",flask,"
Yes, the code in question needs an exception handling mechanism. The `full_dispatch_request` method catches all exceptions raised during the request-response cycle and returns an error response. This is done by calling the `finalize_request` method with a special return value (`rv`) that indicates an error occurred. The `finalize_request` method then handles the error response and sends it to the client.

Therefore, if any exception occurs during the request-response cycle, it will be caught by the `full_dispatch_request` method and handled appropriately. This ensures that any errors or exceptions raised during the handling of a request do not cause the server to crash or terminate abnormally."
/home/r4ph/desenv/exception-miner-multi/projects/py/flask/src/flask/sansio/blueprints.py,__init__,"def __init__(
        self,
        blueprint: Blueprint,
        app: App,
        options: t.Any,
        first_registration: bool,
    ) -> None:
        #: a reference to the current application
        self.app = app

        #: a reference to the blueprint that created this setup state.
        self.blueprint = blueprint

        #: a dictionary with all options that were passed to the
        #: :meth:`~flask.Flask.register_blueprint` method.
        self.options = options

        #: as blueprints can be registered multiple times with the
        #: application and not everything wants to be registered
        #: multiple times on it, this attribute can be used to figure
        #: out if the blueprint was registered in the past already.
        self.first_registration = first_registration

        subdomain = self.options.get(""subdomain"")
        if subdomain is None:
            subdomain = self.blueprint.subdomain

        #: The subdomain that the blueprint should be active for, ``None``
        #: otherwise.
        self.subdomain = subdomain

        url_prefix = self.options.get(""url_prefix"")
        if url_prefix is None:
            url_prefix = self.blueprint.url_prefix
        #: The prefix that should be used for all URLs defined on the
        #: blueprint.
        self.url_prefix = url_prefix

        self.name = self.options.get(""name"", blueprint.name)
        self.name_prefix = self.options.get(""name_prefix"", """")

        #: A dictionary with URL defaults that is added to each and every
        #: URL that was defined with the blueprint.
        self.url_defaults = dict(self.blueprint.url_values_defaults)
        self.url_defaults.update(self.options.get(""url_defaults"", ()))",,0,0,0,0,0,0,0,0,0,0,,,,0,0,0,,flask,"
Yes, this code needs an exception handling mechanism because it is using `dict.get()` method which may raise a `KeyError` if the specified key is not found in the dictionary. Additionally, the `url_defaults` attribute is set to a `dict` that is updated with the results of calling `dict.update()`, which may also raise a `KeyError` if the dictionary being updated does not contain the specified keys. Therefore, it is important to handle any potential exceptions raised by these methods in order to prevent them from propagating and causing issues within the application."
/home/r4ph/desenv/exception-miner-multi/projects/py/flask/tests/test_blueprints.py,view,"def view():
        return """"",,0,0,0,0,0,0,0,0,0,0,,,,0,0,0,,flask,"
No, the code does not require any exception handling mechanism because it returns an empty string, which is a valid response."
/home/r4ph/desenv/exception-miner-multi/projects/py/flask/src/flask/debughelpers.py,attach_enctype_error_multidict,"def attach_enctype_error_multidict(request: Request) -> None:
    """"""Patch ``request.files.__getitem__`` to raise a descriptive error
    about ``enctype=multipart/form-data``.

    :param request: The request to patch.
    :meta private:
    """"""
    oldcls = request.files.__class__

    class newcls(oldcls):  # type: ignore[valid-type, misc]
        def __getitem__(self, key: str) -> t.Any:
            try:
                return super().__getitem__(key)
            except KeyError as e:
                if key not in request.form:
                    raise

                raise DebugFilesKeyError(request, key).with_traceback(
                    e.__traceback__
                ) from None

    newcls.__name__ = oldcls.__name__
    newcls.__module__ = oldcls.__module__
    request.files.__class__ = newcls",,1,0,0,0,2,0,0,0,0,1,KeyError,,"if key not in request.form:
                    raise

                raise DebugFilesKeyError(request, key).with_traceback(
                    e.__traceback__
                ) from None",0,0,0,"def attach_enctype_error_multidict(request: Request) -> None:
    """"""Patch ``request.files.__getitem__`` to raise a descriptive error
    about ``enctype=multipart/form-data``.

    :param request: The request to patch.
    :meta private:
    """"""
    oldcls = request.files.__class__

    class newcls(oldcls):  # type: ignore[valid-type, misc]
        def __getitem__(self, key: str) -> t.Any:
            return super().__getitem__(key)

    newcls.__name__ = oldcls.__name__
    newcls.__module__ = oldcls.__module__
    request.files.__class__ = newcls",flask,"
Yes, this code needs an exception handling mechanism. The function defines a new class (``newcls``) that inherits from ``oldcls`` and overrides the ``__getitem__`` method. However, it does not handle any exceptions that may be raised during the execution of this method. It is important to add appropriate error handling mechanisms to ensure that the code can gracefully handle any errors that may occur while patching the request object."
/home/r4ph/desenv/exception-miner-multi/projects/py/flask/tests/test_cli.py,testcmd,"def testcmd():
        click.echo(current_app.name)",,0,0,0,0,0,0,0,0,0,0,,,,0,0,0,,flask,"
No, this code does not appear to require exception handling. The `click.echo()` function is called within a try-except block, which would only be necessary if the function was being called from within a context where an exception could potentially be raised. However, in this case, the function is being defined as part of a Flask application, and it does not appear to be possible for an exception to be raised at this point in the code. Therefore, there is no need to include an exception handling mechanism in this code snippet."
/home/r4ph/desenv/exception-miner-multi/projects/py/flask/src/flask/json/tag.py,check,"def check(self, value: t.Any) -> bool:
        return isinstance(value, bytes)",,0,0,0,0,0,0,0,0,0,0,,,,0,0,0,,flask,"
Yes, this code needs an exception handling mechanism because it is using `isinstance()` which can raise a `TypeError` if the value passed in is not an instance of `bytes`."
/home/r4ph/desenv/exception-miner-multi/projects/py/flask/tests/test_appctx.py,test_app_tearing_down_with_handled_exception_by_except_block,"def test_app_tearing_down_with_handled_exception_by_except_block(app):
    cleanup_stuff = []

    @app.teardown_appcontext
    def cleanup(exception):
        cleanup_stuff.append(exception)

    with app.app_context():
        try:
            raise Exception(""dummy"")
        except Exception:
            pass

    assert cleanup_stuff == [None]",,1,1,0,1,1,1,0,0,0,0,Exception,Exception,pass,0,0,0,"def test_app_tearing_down_with_handled_exception_by_except_block(app):
    cleanup_stuff = []

    @app.teardown_appcontext
    def cleanup(exception):
        cleanup_stuff.append(exception)

    with app.app_context():
        raise Exception(""dummy"")

    assert cleanup_stuff == [None]",flask,"
Yes, this code needs an exception handling mechanism because it is possible for the `cleanup` function to raise an exception during execution. The `except` block should be used to handle any exceptions that may occur in the `cleanup` function."
/home/r4ph/desenv/exception-miner-multi/projects/py/flask/tests/conftest.py,_reset_os_environ,"def _reset_os_environ(monkeypatch, _standard_os_environ):
    """"""Reset ``os.environ`` to the standard environ after each test,
    in case a test changed something without cleaning up.
    """"""
    monkeypatch._setitem.extend(_standard_os_environ)",,0,0,0,0,0,0,0,0,0,0,,,,0,0,0,,flask,"
Yes, this code needs an exception handling mechanism. The `_setitem` method is called on `monkeypatch` object, which may raise an error if the key being set already exists in the environment. Therefore, it is necessary to handle any exceptions that may be raised by calling this method."
/home/r4ph/desenv/exception-miner-multi/projects/py/flask/examples/tutorial/flaskr/auth.py,register,"def register():
    """"""Register a new user.

    Validates that the username is not already taken. Hashes the
    password for security.
    """"""
    if request.method == ""POST"":
        username = request.form[""username""]
        password = request.form[""password""]
        db = get_db()
        error = None

        if not username:
            error = ""Username is required.""
        elif not password:
            error = ""Password is required.""

        if error is None:
            try:
                db.execute(
                    ""INSERT INTO user (username, password) VALUES (?, ?)"",
                    (username, generate_password_hash(password)),
                )
                db.commit()
            except db.IntegrityError:
                # The username was already taken, which caused the
                # commit to fail. Show a validation error.
                error = f""User {username} is already registered.""
            else:
                # Success, go to the login page.
                return redirect(url_for(""auth.login""))

        flash(error)

    return render_template(""auth/register.html"")",,1,0,0,0,0,0,0,0,1,0,db IntegrityError,,"error = f""User {username} is already registered.""",0,0,0,"def register():
    """"""Register a new user.

    Validates that the username is not already taken. Hashes the
    password for security.
    """"""
    if request.method == ""POST"":
        username = request.form[""username""]
        password = request.form[""password""]
        db = get_db()
        error = None

        if not username:
            error = ""Username is required.""
        elif not password:
            error = ""Password is required.""

        if error is None:
            db.execute(
                    ""INSERT INTO user (username, password) VALUES (?, ?)"",
                    (username, generate_password_hash(password)),
                )
                db.commit()

        flash(error)

    return render_template(""auth/register.html"")",flask,"
Yes, this code needs an exception handling mechanism. The `generate_password_hash()` function is called in the code without any error checking to ensure that it does not raise any exceptions. If the function raises an exception, the code will not handle it and will result in a server error or a crash. To prevent this, we need to add some exception handling mechanism such as `try...except` block to catch any exceptions raised by the `generate_password_hash()` function."
/home/r4ph/desenv/exception-miner-multi/projects/py/flask/tests/typing/typing_route.py,tuple_status,"def tuple_status(code: int = 200) -> tuple[str, int]:
    return ""hello"", code",,0,0,0,0,0,0,0,0,0,0,,,,0,0,0,,flask,"
Yes, this code needs an exception handling mechanism as it raises a `TypeError` when the parameter `code` is not an integer."
/home/r4ph/desenv/exception-miner-multi/projects/py/flask/tests/test_signals.py,index,"def index():
        raise ZeroDivisionError",,0,0,0,0,1,0,0,0,0,0,,ZeroDivisionError,,0,0,0,,flask,"
Yes, this code needs an exception handling mechanism because it raises a `ZeroDivisionError` which is an error that can be handled using an `except` block in Python. If the code were to run without any exception handling, the program would stop executing and display an error message on the console."
/home/r4ph/desenv/exception-miner-multi/projects/py/flask/tests/test_templating.py,index,"def index():
        return flask.render_template_string(""{{ config }}"", config=42)",,0,0,0,0,0,0,0,0,0,0,,,,0,0,0,,flask,"
No, this code does not require any exception handling mechanism. The `render_template_string` function in Flask already handles exceptions and returns a proper HTTP response."
/home/r4ph/desenv/exception-miner-multi/projects/py/flask/src/flask/ctx.py,match_request,"def match_request(self) -> None:
        """"""Can be overridden by a subclass to hook into the matching
        of the request.
        """"""
        try:
            result = self.url_adapter.match(return_rule=True)  # type: ignore
            self.request.url_rule, self.request.view_args = result  # type: ignore
        except HTTPException as e:
            self.request.routing_exception = e",,1,0,0,0,0,0,0,0,0,0,HTTPException,,self.request.routing_exception = e,0,0,0,"def match_request(self) -> None:
        """"""Can be overridden by a subclass to hook into the matching
        of the request.
        """"""
        result = self.url_adapter.match(return_rule=True)  # type: ignore
            self.request.url_rule, self.request.view_args = result  # type: ignore",flask,"
Yes, the code snippet provided requires an exception handling mechanism as it contains a `try` statement but does not include any `except` clauses. The `try` statement is used to catch and handle exceptions raised by the `url_adapter.match()` method call. However, without the `except` clause, any exceptions that may be raised will propagate upwards and potentially crash the application.

It would be best to include an `except` clause in the code snippet to properly handle any exceptions that may be raised during the execution of this method. For example:
```python
def match_request(self) -> None:
    """"""Can be overridden by a subclass to hook into the matching of the request.""""""
    try:
        result = self.url_adapter.match(return_rule=True)  # type: ignore
        self.request.url_rule, self.request.view_args = result  # type: ignore
    except Exception as e:
        print(""Error while matching request:"", str(e))
```"
/home/r4ph/desenv/exception-miner-multi/projects/py/flask/src/flask/cli.py,find_best_app,"def find_best_app(module: ModuleType) -> Flask:
    """"""Given a module instance this tries to find the best possible
    application in the module or raises an exception.
    """"""
    from . import Flask

    # Search for the most common names first.
    for attr_name in (""app"", ""application""):
        app = getattr(module, attr_name, None)

        if isinstance(app, Flask):
            return app

    # Otherwise find the only object that is a Flask instance.
    matches = [v for v in module.__dict__.values() if isinstance(v, Flask)]

    if len(matches) == 1:
        return matches[0]
    elif len(matches) > 1:
        raise NoAppException(
            ""Detected multiple Flask applications in module""
            f"" '{module.__name__}'. Use '{module.__name__}:name'""
            "" to specify the correct one.""
        )

    # Search for app factory functions.
    for attr_name in (""create_app"", ""make_app""):
        app_factory = getattr(module, attr_name, None)

        if inspect.isfunction(app_factory):
            try:
                app = app_factory()

                if isinstance(app, Flask):
                    return app
            except TypeError as e:
                if not _called_with_wrong_args(app_factory):
                    raise

                raise NoAppException(
                    f""Detected factory '{attr_name}' in module '{module.__name__}',""
                    "" but could not call it without arguments. Use""
                    f"" '{module.__name__}:{attr_name}(args)'""
                    "" to specify arguments.""
                ) from e

    raise NoAppException(
        ""Failed to find Flask application or factory in module""
        f"" '{module.__name__}'. Use '{module.__name__}:name'""
        "" to specify one.""
    )",,1,0,0,0,4,0,0,0,0,0,TypeError,NoAppException NoAppException NoAppException,"if not _called_with_wrong_args(app_factory):
                    raise

                raise NoAppException(
                    f""Detected factory '{attr_name}' in module '{module.__name__}',""
                    "" but could not call it without arguments. Use""
                    f"" '{module.__name__}:{attr_name}(args)'""
                    "" to specify arguments.""
                ) from e",0,0,0,"def find_best_app(module: ModuleType) -> Flask:
    """"""Given a module instance this tries to find the best possible
    application in the module or raises an exception.
    """"""
    from . import Flask

    # Search for the most common names first.
    for attr_name in (""app"", ""application""):
        app = getattr(module, attr_name, None)

        if isinstance(app, Flask):
            return app

    # Otherwise find the only object that is a Flask instance.
    matches = [v for v in module.__dict__.values() if isinstance(v, Flask)]

    if len(matches) == 1:
        return matches[0]
    elif len(matches) > 1:
        raise NoAppException(
            ""Detected multiple Flask applications in module""
            f"" '{module.__name__}'. Use '{module.__name__}:name'""
            "" to specify the correct one.""
        )

    # Search for app factory functions.
    for attr_name in (""create_app"", ""make_app""):
        app_factory = getattr(module, attr_name, None)

        if inspect.isfunction(app_factory):
            app = app_factory()

                if isinstance(app, Flask):
                    return app

    raise NoAppException(
        ""Failed to find Flask application or factory in module""
        f"" '{module.__name__}'. Use '{module.__name__}:name'""
        "" to specify one.""
    )",flask,"
Yes, the code needs an exception handling mechanism. The `find_best_app` function raises several exceptions, including `NoAppException`, which is not explicitly handled in the code.

The function first tries to find an `app` attribute on the module instance, and if it doesn't exist, searches for a `create_app` or `make_app` factory function. If no `app` or factory function is found, the function raises a `NoAppException`.

However, if an exception is raised while executing the code inside the `find_best_app` function, the caller won't be able to handle it. To fix this issue, we need to add a try-except block around the code that can raise exceptions, and catch any such exceptions in the except clause.

For example:
```python
try:
    app = find_best_app(module)
except NoAppException as e:
    # Handle the exception here
    pass
```
By adding this try-except block, we can ensure that any exceptions raised by `find_best_app` are caught and handled properly."
/home/r4ph/desenv/exception-miner-multi/projects/py/flask/examples/tutorial/flaskr/db.py,init_app,"def init_app(app):
    """"""Register database functions with the Flask app. This is called by
    the application factory.
    """"""
    app.teardown_appcontext(close_db)
    app.cli.add_command(init_db_command)",,0,0,0,0,0,0,0,0,0,0,,,,0,0,0,,flask,"
Yes, this code needs an exception handling mechanism because it is calling the `close_db` function in the `teardown_appcontext` method of the Flask app, which may raise an exception if the database connection is not properly closed. Additionally, the `init_db_command` command is being added to the Flask app's CLI using the `cli.add_command` method, which may also raise an exception if the command cannot be added for some reason. Therefore, it is important to add appropriate try-except blocks around these calls to ensure that any exceptions that occur are properly handled and reported."
/home/r4ph/desenv/exception-miner-multi/projects/py/flask/src/flask/cli.py,shell_command,"def shell_command() -> None:
    """"""Run an interactive Python shell in the context of a given
    Flask application.  The application will populate the default
    namespace of this shell according to its configuration.

    This is useful for executing small snippets of management code
    without having to manually configure the application.
    """"""
    import code

    banner = (
        f""Python {sys.version} on {sys.platform}\n""
        f""App: {current_app.import_name}\n""
        f""Instance: {current_app.instance_path}""
    )
    ctx: dict[str, t.Any] = {}

    # Support the regular Python interpreter startup script if someone
    # is using it.
    startup = os.environ.get(""PYTHONSTARTUP"")
    if startup and os.path.isfile(startup):
        with open(startup) as f:
            eval(compile(f.read(), startup, ""exec""), ctx)

    ctx.update(current_app.make_shell_context())

    # Site, customize, or startup script can set a hook to call when
    # entering interactive mode. The default one sets up readline with
    # tab and history completion.
    interactive_hook = getattr(sys, ""__interactivehook__"", None)

    if interactive_hook is not None:
        try:
            import readline
            from rlcompleter import Completer
        except ImportError:
            pass
        else:
            # rlcompleter uses __main__.__dict__ by default, which is
            # flask.__main__. Use the shell context instead.
            readline.set_completer(Completer(ctx).complete)

        interactive_hook()

    code.interact(banner=banner, local=ctx)",,1,1,0,0,0,0,0,0,1,0,ImportError,,pass,0,0,0,"def shell_command() -> None:
    """"""Run an interactive Python shell in the context of a given
    Flask application.  The application will populate the default
    namespace of this shell according to its configuration.

    This is useful for executing small snippets of management code
    without having to manually configure the application.
    """"""
    import code

    banner = (
        f""Python {sys.version} on {sys.platform}\n""
        f""App: {current_app.import_name}\n""
        f""Instance: {current_app.instance_path}""
    )
    ctx: dict[str, t.Any] = {}

    # Support the regular Python interpreter startup script if someone
    # is using it.
    startup = os.environ.get(""PYTHONSTARTUP"")
    if startup and os.path.isfile(startup):
        with open(startup) as f:
            eval(compile(f.read(), startup, ""exec""), ctx)

    ctx.update(current_app.make_shell_context())

    # Site, customize, or startup script can set a hook to call when
    # entering interactive mode. The default one sets up readline with
    # tab and history completion.
    interactive_hook = getattr(sys, ""__interactivehook__"", None)

    if interactive_hook is not None:
        import readline
            from rlcompleter import Completer

        interactive_hook()

    code.interact(banner=banner, local=ctx)",flask,"
Yes, this code needs an exception handling mechanism. The `startup` variable is set to the value of the `PYTHONSTARTUP` environment variable, which may not exist or be a file. If it's a file, but the file cannot be read, the `eval()` function will raise a `FileNotFoundError`. Additionally, if the `startup` file contains syntax errors, the `eval()` function will raise a `SyntaxError`.

To handle these exceptions, you can use a try-except block to catch the `FileNotFoundError` and `SyntaxError` exceptions. For example:
```
try:
    startup = os.environ.get(""PYTHONSTARTUP"")
    if startup and os.path.isfile(startup):
        with open(startup) as f:
            eval(compile(f.read(), startup, ""exec""), ctx)
except (FileNotFoundError, SyntaxError) as e:
    print(e)
```
This will catch any `FileNotFoundError` or `SyntaxError` exceptions that are raised during the execution of the code in the `startup` file and print an error message to the console."
/home/r4ph/desenv/exception-miner-multi/projects/py/flask/src/flask/cli.py,_env_file_callback,"def _env_file_callback(
    ctx: click.Context, param: click.Option, value: str | None
) -> str | None:
    if value is None:
        return None

    import importlib

    try:
        importlib.import_module(""dotenv"")
    except ImportError:
        raise click.BadParameter(
            ""python-dotenv must be installed to load an env file."",
            ctx=ctx,
            param=param,
        ) from None

    # Don't check FLASK_SKIP_DOTENV, that only disables automatically
    # loading .env and .flaskenv files.
    load_dotenv(value)
    return value",,1,0,0,0,1,0,0,0,0,0,ImportError,,"raise click.BadParameter(
            ""python-dotenv must be installed to load an env file."",
            ctx=ctx,
            param=param,
        ) from None",0,0,0,"def _env_file_callback(
    ctx: click.Context, param: click.Option, value: str | None
) -> str | None:
    if value is None:
        return None

    import importlib

    importlib.import_module(""dotenv"")

    # Don't check FLASK_SKIP_DOTENV, that only disables automatically
    # loading .env and .flaskenv files.
    load_dotenv(value)
    return value",flask,"
Yes, the code snippet provided is not handling any exceptions that may occur while importing the `dotenv` module using `importlib`. The function `_env_file_callback()` calls the `load_dotenv()` method to load environment variables from a specified file, but it does not catch any potential errors that may occur during this process. Therefore, it is recommended to add an exception handling mechanism to ensure that any errors related to importing or loading environment variables are handled gracefully."
/home/r4ph/desenv/exception-miner-multi/projects/py/flask/src/flask/ctx.py,__delattr__,"def __delattr__(self, name: str) -> None:
        try:
            del self.__dict__[name]
        except KeyError:
            raise AttributeError(name) from None",,1,0,0,0,1,0,0,0,0,0,KeyError,AttributeError,raise AttributeError(name) from None,0,0,0,"def __delattr__(self, name: str) -> None:
        del self.__dict__[name]",flask,"
Yes, this code needs an exception handling mechanism. The `__delattr__` method is called when a user tries to delete an attribute from an object, and it raises a `KeyError` if the attribute does not exist in the object's dictionary. To handle this case gracefully, you can use a try-except block to catch the `KeyError` exception and provide a custom message to the user. For example:
```
try:
    del self.__dict__[name]
except KeyError:
    print(f""Attribute {name} does not exist in object"")
```
By doing this, you can avoid raising the `KeyError` exception and provide a more informative message to the user."
/home/r4ph/desenv/exception-miner-multi/projects/py/flask/tests/test_helpers.py,test_abort_with_app,"def test_abort_with_app(app):
    class My900Error(werkzeug.exceptions.HTTPException):
        code = 900

    app.aborter.mapping[900] = My900Error

    with app.app_context(), pytest.raises(My900Error):
        flask.abort(900)",,0,0,0,0,0,0,0,0,0,0,,,,0,0,0,,flask,"
Yes, this code needs an exception handling mechanism. The `test_abort_with_app` function creates a new HTTP exception class called `My900Error` and assigns it to the `aborter.mapping` dictionary of the Flask app. However, the code does not handle any exceptions that may be raised when calling `flask.abort(900)`.

To handle any potential errors that may occur during the execution of this function, you can add a `try...except` block to catch and handle any exceptions that may be raised. For example:
```
def test_abort_with_app(app):
    class My900Error(werkzeug.exceptions.HTTPException):
        code = 900

    app.aborter.mapping[900] = My900Error

    with app.app_context():
        try:
            flask.abort(900)
        except My900Error as e:
            # Handle the error here
```
By adding a `try...except` block, you can catch any exceptions that may be raised during the execution of the function and handle them appropriately. This ensures that any errors that occur during the test are handled in a consistent manner, which can help improve the reliability and maintainability of your code."
/home/r4ph/desenv/exception-miner-multi/projects/py/flask/src/flask/sansio/app.py,handle_url_build_error,"def handle_url_build_error(
        self, error: BuildError, endpoint: str, values: dict[str, t.Any]
    ) -> str:
        """"""Called by :meth:`.url_for` if a
        :exc:`~werkzeug.routing.BuildError` was raised. If this returns
        a value, it will be returned by ``url_for``, otherwise the error
        will be re-raised.

        Each function in :attr:`url_build_error_handlers` is called with
        ``error``, ``endpoint`` and ``values``. If a function returns
        ``None`` or raises a ``BuildError``, it is skipped. Otherwise,
        its return value is returned by ``url_for``.

        :param error: The active ``BuildError`` being handled.
        :param endpoint: The endpoint being built.
        :param values: The keyword arguments passed to ``url_for``.
        """"""
        for handler in self.url_build_error_handlers:
            try:
                rv = handler(error, endpoint, values)
            except BuildError as e:
                # make error available outside except block
                error = e
            else:
                if rv is not None:
                    return rv

        # Re-raise if called with an active exception, otherwise raise
        # the passed in exception.
        if error is sys.exc_info()[1]:
            raise

        raise error",,1,0,0,0,2,0,0,1,1,0,BuildError,error,error = e,0,0,0,"def handle_url_build_error(
        self, error: BuildError, endpoint: str, values: dict[str, t.Any]
    ) -> str:
        """"""Called by :meth:`.url_for` if a
        :exc:`~werkzeug.routing.BuildError` was raised. If this returns
        a value, it will be returned by ``url_for``, otherwise the error
        will be re-raised.

        Each function in :attr:`url_build_error_handlers` is called with
        ``error``, ``endpoint`` and ``values``. If a function returns
        ``None`` or raises a ``BuildError``, it is skipped. Otherwise,
        its return value is returned by ``url_for``.

        :param error: The active ``BuildError`` being handled.
        :param endpoint: The endpoint being built.
        :param values: The keyword arguments passed to ``url_for``.
        """"""
        for handler in self.url_build_error_handlers:
            rv = handler(error, endpoint, values)

        # Re-raise if called with an active exception, otherwise raise
        # the passed in exception.
        if error is sys.exc_info()[1]:
            raise

        raise error",flask,"
Yes, this code appears to need an exception handling mechanism. The `handle_url_build_error` function is designed to handle exceptions raised by the `url_for` method, and it calls each handler in the `url_build_error_handlers` list with the exception as an argument. If any of these handlers return a value or raise a new exception, it will be returned by `url_for`. However, if no handler returns a value or raises a new exception, the original exception is re-raised.

Therefore, this function needs to handle exceptions in some way, either by returning a value or raising a new exception. Otherwise, it would return without any indication of whether an error occurred or not, which could lead to unexpected behavior and potentially cause bugs in the program."
/home/r4ph/desenv/exception-miner-multi/projects/py/flask/tests/test_basic.py,index,"def index():
        flask.session[""testing""] = 42
        return ""Hello World""",,0,0,0,0,0,0,0,0,0,0,,,,0,0,0,,flask,"
Yes, this code snippet needs exception handling because it assigns a value to `flask.session[""testing""]` without checking whether the key exists in the session dictionary beforehand. If the key does not exist, then attempting to access it will raise a `KeyError`. Therefore, it is important to handle this exception and ensure that the code does not crash when an error occurs."
/home/r4ph/desenv/exception-miner-multi/projects/py/flask/src/flask/ctx.py,__init__,"def __init__(self, app: Flask) -> None:
        self.app = app
        self.url_adapter = app.create_url_adapter(None)
        self.g: _AppCtxGlobals = app.app_ctx_globals_class()
        self._cv_tokens: list[contextvars.Token[AppContext]] = []",,0,0,0,0,0,0,0,0,0,0,,,,0,0,0,,flask,"
Yes, this code needs an exception handling mechanism. The `__init__` method is responsible for initializing the instance of the class, and it raises an error if any of the initialization steps fail. To handle errors in this case, you can wrap the entire method body in a `try-except` block and catch any exceptions that may occur during initialization. Additionally, you may also consider adding a `finally` clause to ensure that the context variables are properly cleaned up even if an error occurs."
/home/r4ph/desenv/exception-miner-multi/projects/py/flask/tests/test_basic.py,test_session,"def test_session(app, client):
    @app.route(""/set"", methods=[""POST""])
    def set():
        assert not flask.session.accessed
        assert not flask.session.modified
        flask.session[""value""] = flask.request.form[""value""]
        assert flask.session.accessed
        assert flask.session.modified
        return ""value set""

    @app.route(""/get"")
    def get():
        assert not flask.session.accessed
        assert not flask.session.modified
        v = flask.session.get(""value"", ""None"")
        assert flask.session.accessed
        assert not flask.session.modified
        return v

    assert client.post(""/set"", data={""value"": ""42""}).data == b""value set""
    assert client.get(""/get"").data == b""42""",,0,0,0,0,0,0,0,0,0,0,,,,0,0,0,,flask,"
Yes, this code needs an exception handling mechanism because it is using the `flask` module which can raise exceptions such as `KeyError`, `TypeError`, and `RuntimeError`. The best way to handle these exceptions would be to use try-except blocks to catch them and return a custom error message or log the error. Additionally, it's also important to validate the input data before using it in any operation to avoid unexpected behavior."
/home/r4ph/desenv/exception-miner-multi/projects/py/flask/tests/test_appctx.py,cleanup,"def cleanup(exception):
        cleanup_stuff.append(exception)",,0,0,0,0,0,0,0,0,0,0,,,,0,0,0,,flask,"
Yes, the provided code needs an exception handling mechanism. The `cleanup` function is defined as taking an argument named `exception`, but it does not appear to be doing anything with that argument. This means that if an exception occurs while running the function, the exception will be lost and not properly handled.

To fix this issue, you can add a try-except block around the code in the `cleanup` function, like this:
```
def cleanup(exception):
    try:
        # Do some stuff with the exception
        print(f""Exception {exception} occurred"")
    except Exception as e:
        # Handle the exception here
        print(f""Exception {e} occurred"")
```
This way, if an exception occurs while running the `cleanup` function, it will be caught and handled properly."
/home/r4ph/desenv/exception-miner-multi/projects/py/flask/src/flask/sansio/scaffold.py,_find_package_path,"def _find_package_path(import_name: str) -> str:
    """"""Find the path that contains the package or module.""""""
    root_mod_name, _, _ = import_name.partition(""."")

    try:
        root_spec = importlib.util.find_spec(root_mod_name)

        if root_spec is None:
            raise ValueError(""not found"")
    except (ImportError, ValueError):
        # ImportError: the machinery told us it does not exist
        # ValueError:
        #    - the module name was invalid
        #    - the module name is __main__
        #    - we raised `ValueError` due to `root_spec` being `None`
        return os.getcwd()

    if root_spec.submodule_search_locations:
        if root_spec.origin is None or root_spec.origin == ""namespace"":
            # namespace package
            package_spec = importlib.util.find_spec(import_name)

            if package_spec is not None and package_spec.submodule_search_locations:
                # Pick the path in the namespace that contains the submodule.
                package_path = pathlib.Path(
                    os.path.commonpath(package_spec.submodule_search_locations)
                )
                search_location = next(
                    location
                    for location in root_spec.submodule_search_locations
                    if _path_is_relative_to(package_path, location)
                )
            else:
                # Pick the first path.
                search_location = root_spec.submodule_search_locations[0]

            return os.path.dirname(search_location)
        else:
            # package with __init__.py
            return os.path.dirname(os.path.dirname(root_spec.origin))
    else:
        # module
        return os.path.dirname(root_spec.origin)  # type: ignore[type-var, return-value]",,1,0,0,0,1,0,0,0,0,0,ImportError ValueError,ValueError,return os.getcwd(),0,0,0,"def _find_package_path(import_name: str) -> str:
    """"""Find the path that contains the package or module.""""""
    root_mod_name, _, _ = import_name.partition(""."")

    root_spec = importlib.util.find_spec(root_mod_name)

        if root_spec is None:
            raise ValueError(""not found"")

    if root_spec.submodule_search_locations:
        if root_spec.origin is None or root_spec.origin == ""namespace"":
            # namespace package
            package_spec = importlib.util.find_spec(import_name)

            if package_spec is not None and package_spec.submodule_search_locations:
                # Pick the path in the namespace that contains the submodule.
                package_path = pathlib.Path(
                    os.path.commonpath(package_spec.submodule_search_locations)
                )
                search_location = next(
                    location
                    for location in root_spec.submodule_search_locations
                    if _path_is_relative_to(package_path, location)
                )
            else:
                # Pick the first path.
                search_location = root_spec.submodule_search_locations[0]

            return os.path.dirname(search_location)
        else:
            # package with __init__.py
            return os.path.dirname(os.path.dirname(root_spec.origin))
    else:
        # module
        return os.path.dirname(root_spec.origin)  # type: ignore[type-var, return-value]",flask,"
Yes, this code needs an exception handling mechanism because it raises a `ValueError` if the package or module is not found. The `find_package_path()` function assumes that the package or module exists and returns its path without verifying whether it actually exists. Therefore, it is important to handle the case where the package or module does not exist in order to avoid raising an exception and crashing the program."
/home/r4ph/desenv/exception-miner-multi/projects/py/flask/src/flask/sansio/scaffold.py,_get_exc_class_and_code,"def _get_exc_class_and_code(
        exc_class_or_code: type[Exception] | int,
    ) -> tuple[type[Exception], int | None]:
        """"""Get the exception class being handled. For HTTP status codes
        or ``HTTPException`` subclasses, return both the exception and
        status code.

        :param exc_class_or_code: Any exception class, or an HTTP status
            code as an integer.
        """"""
        exc_class: type[Exception]

        if isinstance(exc_class_or_code, int):
            try:
                exc_class = default_exceptions[exc_class_or_code]
            except KeyError:
                raise ValueError(
                    f""'{exc_class_or_code}' is not a recognized HTTP""
                    "" error code. Use a subclass of HTTPException with""
                    "" that code instead.""
                ) from None
        else:
            exc_class = exc_class_or_code

        if isinstance(exc_class, Exception):
            raise TypeError(
                f""{exc_class!r} is an instance, not a class. Handlers""
                "" can only be registered for Exception classes or HTTP""
                "" error codes.""
            )

        if not issubclass(exc_class, Exception):
            raise ValueError(
                f""'{exc_class.__name__}' is not a subclass of Exception.""
                "" Handlers can only be registered for Exception classes""
                "" or HTTP error codes.""
            )

        if issubclass(exc_class, HTTPException):
            return exc_class, exc_class.code
        else:
            return exc_class, None",,1,0,0,0,3,0,0,0,0,0,KeyError,ValueError TypeError ValueError,"raise ValueError(
                    f""'{exc_class_or_code}' is not a recognized HTTP""
                    "" error code. Use a subclass of HTTPException with""
                    "" that code instead.""
                ) from None",0,0,0,"def _get_exc_class_and_code(
        exc_class_or_code: type[Exception] | int,
    ) -> tuple[type[Exception], int | None]:
        """"""Get the exception class being handled. For HTTP status codes
        or ``HTTPException`` subclasses, return both the exception and
        status code.

        :param exc_class_or_code: Any exception class, or an HTTP status
            code as an integer.
        """"""
        exc_class: type[Exception]

        if isinstance(exc_class_or_code, int):
            exc_class = default_exceptions[exc_class_or_code]
        else:
            exc_class = exc_class_or_code

        if isinstance(exc_class, Exception):
            raise TypeError(
                f""{exc_class!r} is an instance, not a class. Handlers""
                "" can only be registered for Exception classes or HTTP""
                "" error codes.""
            )

        if not issubclass(exc_class, Exception):
            raise ValueError(
                f""'{exc_class.__name__}' is not a subclass of Exception.""
                "" Handlers can only be registered for Exception classes""
                "" or HTTP error codes.""
            )

        if issubclass(exc_class, HTTPException):
            return exc_class, exc_class.code
        else:
            return exc_class, None",flask,"
Yes, this code needs an exception handling mechanism. The function `get_exc_class_and_code` raises a `TypeError` and a `ValueError` when the input `exc_class_or_code` is not an instance of `Exception` or a subclass of `Exception`, respectively. These exceptions indicate that there was an error in the input provided, which should be handled appropriately by the calling code."
/home/r4ph/desenv/exception-miner-multi/projects/py/flask/tests/test_json.py,_has_encoding,"def _has_encoding(name):
    try:
        import codecs

        codecs.lookup(name)
        return True
    except LookupError:
        return False",,1,0,0,0,0,0,0,0,0,1,LookupError,,return False,0,0,0,"def _has_encoding(name):
    import codecs

        codecs.lookup(name)
        return True",flask,"
Yes, this code needs an exception handling mechanism because it is using the `codecs.lookup()` function, which may raise a `LookupError` if the encoding name is not recognized. Therefore, the code should be modified to catch and handle the `LookupError` exception."
/home/r4ph/desenv/exception-miner-multi/projects/py/flask/src/flask/cli.py,get_command,"def get_command(self, ctx: click.Context, name: str) -> click.Command | None:
        self._load_plugin_commands()
        # Look up built-in and plugin commands, which should be
        # available even if the app fails to load.
        rv = super().get_command(ctx, name)

        if rv is not None:
            return rv

        info = ctx.ensure_object(ScriptInfo)

        # Look up commands provided by the app, showing an error and
        # continuing if the app couldn't be loaded.
        try:
            app = info.load_app()
        except NoAppException as e:
            click.secho(f""Error: {e.format_message()}\n"", err=True, fg=""red"")
            return None

        # Push an app context for the loaded app unless it is already
        # active somehow. This makes the context available to parameter
        # and command callbacks without needing @with_appcontext.
        if not current_app or current_app._get_current_object() is not app:  # type: ignore[attr-defined]
            ctx.with_resource(app.app_context())

        return app.cli.get_command(ctx, name)",,1,0,0,0,0,0,0,0,0,0,NoAppException,,"click.secho(f""Error: {e.format_message()}\n"", err=True, fg=""red"")
            return None",0,0,0,"def get_command(self, ctx: click.Context, name: str) -> click.Command | None:
        self._load_plugin_commands()
        # Look up built-in and plugin commands, which should be
        # available even if the app fails to load.
        rv = super().get_command(ctx, name)

        if rv is not None:
            return rv

        info = ctx.ensure_object(ScriptInfo)

        # Look up commands provided by the app, showing an error and
        # continuing if the app couldn't be loaded.
        app = info.load_app()

        # Push an app context for the loaded app unless it is already
        # active somehow. This makes the context available to parameter
        # and command callbacks without needing @with_appcontext.
        if not current_app or current_app._get_current_object() is not app:  # type: ignore[attr-defined]
            ctx.with_resource(app.app_context())

        return app.cli.get_command(ctx, name)",flask,"
Yes, the code snippet provided appears to be part of a Python class that extends the `click` library's `Group` class and overrides its `get_command()` method. This method is responsible for retrieving a command object from the Click CLI framework based on the specified name.

However, the method also contains some custom logic that is specific to the `ScriptInfo` class, which is not part of the standard Click library. This means that if an error occurs while loading the app or retrieving the command object, the code will likely raise a `click.ClickException`.

To handle this situation more gracefully and avoid crashing the application, it would be advisable to add some exception handling mechanism, such as a try-except block, around the code that calls the `load_app()` method and retrieves the command object. This will allow the application to continue running even if there is an error while loading the app or retrieving the command object."
/home/r4ph/desenv/exception-miner-multi/projects/py/flask/src/flask/cli.py,run_command,"def run_command(
    info: ScriptInfo,
    host: str,
    port: int,
    reload: bool,
    debugger: bool,
    with_threads: bool,
    cert: ssl.SSLContext | tuple[str, str | None] | t.Literal[""adhoc""] | None,
    extra_files: list[str] | None,
    exclude_patterns: list[str] | None,
) -> None:
    """"""Run a local development server.

    This server is for development purposes only. It does not provide
    the stability, security, or performance of production WSGI servers.

    The reloader and debugger are enabled by default with the '--debug'
    option.
    """"""
    try:
        app: WSGIApplication = info.load_app()
    except Exception as e:
        if is_running_from_reloader():
            # When reloading, print out the error immediately, but raise
            # it later so the debugger or server can handle it.
            traceback.print_exc()
            err = e

            def app(
                environ: WSGIEnvironment, start_response: StartResponse
            ) -> cabc.Iterable[bytes]:
                raise err from None

        else:
            # When not reloading, raise the error immediately so the
            # command fails.
            raise e from None

    debug = get_debug_flag()

    if reload is None:
        reload = debug

    if debugger is None:
        debugger = debug

    show_server_banner(debug, info.app_import_path)

    run_simple(
        host,
        port,
        app,
        use_reloader=reload,
        use_debugger=debugger,
        threaded=with_threads,
        ssl_context=cert,
        extra_files=extra_files,
        exclude_patterns=exclude_patterns,
    )",,1,0,0,1,2,0,0,0,0,0,Exception,err e,"if is_running_from_reloader():
            # When reloading, print out the error immediately, but raise
            # it later so the debugger or server can handle it.
            traceback.print_exc()
            err = e

            def app(
                environ: WSGIEnvironment, start_response: StartResponse
            ) -> cabc.Iterable[bytes]:
                raise err from None

        else:
            # When not reloading, raise the error immediately so the
            # command fails.
            raise e from None",0,0,0,"def run_command(
    info: ScriptInfo,
    host: str,
    port: int,
    reload: bool,
    debugger: bool,
    with_threads: bool,
    cert: ssl.SSLContext | tuple[str, str | None] | t.Literal[""adhoc""] | None,
    extra_files: list[str] | None,
    exclude_patterns: list[str] | None,
) -> None:
    """"""Run a local development server.

    This server is for development purposes only. It does not provide
    the stability, security, or performance of production WSGI servers.

    The reloader and debugger are enabled by default with the '--debug'
    option.
    """"""
    app: WSGIApplication = info.load_app()

    debug = get_debug_flag()

    if reload is None:
        reload = debug

    if debugger is None:
        debugger = debug

    show_server_banner(debug, info.app_import_path)

    run_simple(
        host,
        port,
        app,
        use_reloader=reload,
        use_debugger=debugger,
        threaded=with_threads,
        ssl_context=cert,
        extra_files=extra_files,
        exclude_patterns=exclude_patterns,
    )",flask,"
Yes, this code needs an exception handling mechanism. The `run_simple` function is called without any explicit error handling, which means that any exceptions raised during the execution of the server will not be caught and handled. This could result in unpredictable behavior, such as a crashed server or unexpected errors. It's recommended to use a try-except block to handle any potential exceptions and log them appropriately."
/home/r4ph/desenv/exception-miner-multi/projects/py/flask/src/flask/sessions.py,open_session,"def open_session(self, app: Flask, request: Request) -> SecureCookieSession | None:
        s = self.get_signing_serializer(app)
        if s is None:
            return None
        val = request.cookies.get(self.get_cookie_name(app))
        if not val:
            return self.session_class()
        max_age = int(app.permanent_session_lifetime.total_seconds())
        try:
            data = s.loads(val, max_age=max_age)
            return self.session_class(data)
        except BadSignature:
            return self.session_class()",,1,0,0,0,0,0,0,0,0,1,BadSignature,,return self.session_class(),0,0,0,"def open_session(self, app: Flask, request: Request) -> SecureCookieSession | None:
        s = self.get_signing_serializer(app)
        if s is None:
            return None
        val = request.cookies.get(self.get_cookie_name(app))
        if not val:
            return self.session_class()
        max_age = int(app.permanent_session_lifetime.total_seconds())
        data = s.loads(val, max_age=max_age)
            return self.session_class(data)",flask,"
Yes, this code needs an exception handling mechanism. The `loads` method of the serializer can raise a `SignatureExpired` exception if the signature on the cookie is invalid or has expired. The current code does not handle this case and simply returns `None`. It is recommended to add a try-except block around the call to `loads` to catch this exception and log it, rather than returning `None`."
/home/r4ph/desenv/exception-miner-multi/projects/py/flask/tests/test_helpers.py,index,"def index(self):
            return ""42""",,0,0,0,0,0,0,0,0,0,0,,,,0,0,0,,flask,"
No, this code does not require any exception handling mechanisms because it does not use any methods that can raise exceptions. The `index` method simply returns a string value, and since it does not use any external resources or perform any operations that could potentially fail, there is no need for error handling."
/home/r4ph/desenv/exception-miner-multi/projects/py/flask/src/flask/wrappers.py,on_json_loading_failed,"def on_json_loading_failed(self, e: ValueError | None) -> t.Any:
        try:
            return super().on_json_loading_failed(e)
        except BadRequest as e:
            if current_app and current_app.debug:
                raise

            raise BadRequest() from e",,1,0,0,0,2,0,0,0,0,1,BadRequest,BadRequest,"if current_app and current_app.debug:
                raise

            raise BadRequest() from e",0,0,0,"def on_json_loading_failed(self, e: ValueError | None) -> t.Any:
        return super().on_json_loading_failed(e)",flask,"
No, this code does not require an exception handling mechanism. The function `on_json_loading_failed` is overriding the base class method `on_json_loading_failed` and is returning the result of calling the superclass's implementation, which will return None if no exception occurred during loading. Therefore, there is no need to handle exceptions within this function."
/home/r4ph/desenv/exception-miner-multi/projects/py/flask/tests/test_basic.py,index,"def index():
        flask.session[""test""] = 42
        flask.session.permanent = permanent
        return """"",,0,0,0,0,0,0,0,0,0,0,,,,0,0,0,,flask,"
Yes, this code does need an exception handling mechanism. The `flask.session` object is used in the code, and it may not always be available, depending on the context in which the function is called. If the `flask.session` object is not available, the code will raise a `NameError`.

To handle this situation, you can add a try-except block to catch the `NameError` exception and log the error message or return an error response. For example:
```python
try:
    flask.session[""test""] = 42
    flask.session.permanent = permanent
except NameError as e:
    logger.exception(""Failed to set session variables"")
    return ""Internal server error"", 500
return """"
```
By catching the `NameError` exception, you ensure that the code will not crash if the `flask.session` object is not available, and you can handle the error in a more graceful way."
/home/r4ph/desenv/exception-miner-multi/projects/py/flask/src/flask/cli.py,_validate_key,"def _validate_key(ctx: click.Context, param: click.Parameter, value: t.Any) -> t.Any:
    """"""The ``--key`` option must be specified when ``--cert`` is a file.
    Modifies the ``cert`` param to be a ``(cert, key)`` pair if needed.
    """"""
    cert = ctx.params.get(""cert"")
    is_adhoc = cert == ""adhoc""

    try:
        import ssl
    except ImportError:
        is_context = False
    else:
        is_context = isinstance(cert, ssl.SSLContext)

    if value is not None:
        if is_adhoc:
            raise click.BadParameter(
                'When ""--cert"" is ""adhoc"", ""--key"" is not used.', ctx, param
            )

        if is_context:
            raise click.BadParameter(
                'When ""--cert"" is an SSLContext object, ""--key"" is not used.',
                ctx,
                param,
            )

        if not cert:
            raise click.BadParameter('""--cert"" must also be specified.', ctx, param)

        ctx.params[""cert""] = cert, value

    else:
        if cert and not (is_adhoc or is_context):
            raise click.BadParameter('Required when using ""--cert"".', ctx, param)

    return value",,1,0,0,0,4,0,0,0,1,0,ImportError,,is_context = False,0,0,0,"def _validate_key(ctx: click.Context, param: click.Parameter, value: t.Any) -> t.Any:
    """"""The ``--key`` option must be specified when ``--cert`` is a file.
    Modifies the ``cert`` param to be a ``(cert, key)`` pair if needed.
    """"""
    cert = ctx.params.get(""cert"")
    is_adhoc = cert == ""adhoc""

    import ssl

    if value is not None:
        if is_adhoc:
            raise click.BadParameter(
                'When ""--cert"" is ""adhoc"", ""--key"" is not used.', ctx, param
            )

        if is_context:
            raise click.BadParameter(
                'When ""--cert"" is an SSLContext object, ""--key"" is not used.',
                ctx,
                param,
            )

        if not cert:
            raise click.BadParameter('""--cert"" must also be specified.', ctx, param)

        ctx.params[""cert""] = cert, value

    else:
        if cert and not (is_adhoc or is_context):
            raise click.BadParameter('Required when using ""--cert"".', ctx, param)

    return value",flask,"
Yes, the code includes an `except` block that catches and handles any exceptions that may be raised during the execution of the function. This is necessary because the function uses third-party libraries such as `ssl` and `click`, which can raise various types of exceptions. By including an `except` block, the function is able to handle these exceptions in a predictable way and prevent them from being raised to the caller."
/home/r4ph/desenv/exception-miner-multi/projects/py/flask/tests/test_json.py,test_json_key_sorting,"def test_json_key_sorting(app, client):
    app.debug = True
    assert app.json.sort_keys
    d = dict.fromkeys(range(20), ""foo"")

    @app.route(""/"")
    def index():
        return flask.jsonify(values=d)

    rv = client.get(""/"")
    lines = [x.strip() for x in rv.data.strip().decode(""utf-8"").splitlines()]
    sorted_by_str = [
        ""{"",
        '""values"": {',
        '""0"": ""foo"",',
        '""1"": ""foo"",',
        '""10"": ""foo"",',
        '""11"": ""foo"",',
        '""12"": ""foo"",',
        '""13"": ""foo"",',
        '""14"": ""foo"",',
        '""15"": ""foo"",',
        '""16"": ""foo"",',
        '""17"": ""foo"",',
        '""18"": ""foo"",',
        '""19"": ""foo"",',
        '""2"": ""foo"",',
        '""3"": ""foo"",',
        '""4"": ""foo"",',
        '""5"": ""foo"",',
        '""6"": ""foo"",',
        '""7"": ""foo"",',
        '""8"": ""foo"",',
        '""9"": ""foo""',
        ""}"",
        ""}"",
    ]
    sorted_by_int = [
        ""{"",
        '""values"": {',
        '""0"": ""foo"",',
        '""1"": ""foo"",',
        '""2"": ""foo"",',
        '""3"": ""foo"",',
        '""4"": ""foo"",',
        '""5"": ""foo"",',
        '""6"": ""foo"",',
        '""7"": ""foo"",',
        '""8"": ""foo"",',
        '""9"": ""foo"",',
        '""10"": ""foo"",',
        '""11"": ""foo"",',
        '""12"": ""foo"",',
        '""13"": ""foo"",',
        '""14"": ""foo"",',
        '""15"": ""foo"",',
        '""16"": ""foo"",',
        '""17"": ""foo"",',
        '""18"": ""foo"",',
        '""19"": ""foo""',
        ""}"",
        ""}"",
    ]

    try:
        assert lines == sorted_by_int
    except AssertionError:
        assert lines == sorted_by_str",,1,0,0,0,0,0,0,0,0,0,AssertionError,,assert lines == sorted_by_str,0,0,0,"def test_json_key_sorting(app, client):
    app.debug = True
    assert app.json.sort_keys
    d = dict.fromkeys(range(20), ""foo"")

    @app.route(""/"")
    def index():
        return flask.jsonify(values=d)

    rv = client.get(""/"")
    lines = [x.strip() for x in rv.data.strip().decode(""utf-8"").splitlines()]
    sorted_by_str = [
        ""{"",
        '""values"": {',
        '""0"": ""foo"",',
        '""1"": ""foo"",',
        '""10"": ""foo"",',
        '""11"": ""foo"",',
        '""12"": ""foo"",',
        '""13"": ""foo"",',
        '""14"": ""foo"",',
        '""15"": ""foo"",',
        '""16"": ""foo"",',
        '""17"": ""foo"",',
        '""18"": ""foo"",',
        '""19"": ""foo"",',
        '""2"": ""foo"",',
        '""3"": ""foo"",',
        '""4"": ""foo"",',
        '""5"": ""foo"",',
        '""6"": ""foo"",',
        '""7"": ""foo"",',
        '""8"": ""foo"",',
        '""9"": ""foo""',
        ""}"",
        ""}"",
    ]
    sorted_by_int = [
        ""{"",
        '""values"": {',
        '""0"": ""foo"",',
        '""1"": ""foo"",',
        '""2"": ""foo"",',
        '""3"": ""foo"",',
        '""4"": ""foo"",',
        '""5"": ""foo"",',
        '""6"": ""foo"",',
        '""7"": ""foo"",',
        '""8"": ""foo"",',
        '""9"": ""foo"",',
        '""10"": ""foo"",',
        '""11"": ""foo"",',
        '""12"": ""foo"",',
        '""13"": ""foo"",',
        '""14"": ""foo"",',
        '""15"": ""foo"",',
        '""16"": ""foo"",',
        '""17"": ""foo"",',
        '""18"": ""foo"",',
        '""19"": ""foo""',
        ""}"",
        ""}"",
    ]

    assert lines == sorted_by_int",flask,"
Yes, this code needs an exception handling mechanism. The `d` dictionary is created using `dict.fromkeys()` method, which throws a `KeyError` if any of the keys already exist in the dictionary. This can cause issues if the keys are not properly handled and the test fails with a `KeyError`.

To handle this scenario, you should add a try-except block around the code that uses the dictionary, like this:
```python
try:
    d = dict.fromkeys(range(20), ""foo"")
except KeyError as e:
    # Handle the exception here
```
This will allow the test to continue running even if a `KeyError` is raised during the creation of the dictionary. You can also add more specific handling for the `KeyError`, such as logging the error and continuing with the test."
/home/r4ph/desenv/exception-miner-multi/projects/py/flask/tests/test_views.py,test_endpoint_override,"def test_endpoint_override(app):
    app.debug = True

    class Index(flask.views.View):
        methods = [""GET"", ""POST""]

        def dispatch_request(self):
            return flask.request.method

    app.add_url_rule(""/"", view_func=Index.as_view(""index""))

    with pytest.raises(AssertionError):
        app.add_url_rule(""/"", view_func=Index.as_view(""index""))

    # But these tests should still pass. We just log a warning.
    common_test(app)",,0,0,0,0,0,0,0,0,0,0,,,,0,0,0,,flask,"
Yes, the code needs an exception handling mechanism. The `pytest.raises` decorator is used to test that an error is raised when adding a duplicate URL rule. If the test fails, it will raise an `AssertionError`, which needs to be caught and handled appropriately.

In this case, the best approach would be to catch the exception using a try-except block, like this:
```
try:
    app.add_url_rule(""/"", view_func=Index.as_view(""index""))
except AssertionError as e:
    # Handle the error here
    pass
```
This will ensure that any errors raised by the test are properly handled and not allowed to propagate up to the calling code, which may result in unexpected behavior or even a crash."
/home/r4ph/desenv/exception-miner-multi/projects/py/flask/tests/test_json.py,add,"def add():
        json = flask.request.get_json()
        return str(json[""a""] + json[""b""])",,0,0,0,0,0,0,0,0,0,0,,,,0,0,0,,flask,"
No, this code does not require exception handling. It only accesses the ""a"" and ""b"" fields of the JSON object that is passed as an argument to the function, so it should be safe from any exceptions related to accessing those fields. However, if the input JSON does not have the ""a"" or ""b"" fields, the code will raise a KeyError, which can be handled using try-except block."
/home/r4ph/desenv/exception-miner-multi/projects/py/flask/tests/test_cli.py,exit,"def exit(self):
            return",,0,0,0,0,0,0,0,0,0,0,,,,0,0,0,,flask,"
No, the code does not need an exception handling mechanism. The `exit` function in Python simply returns nothing and does not throw any errors. Therefore, it is not necessary to use an exception handling mechanism to handle the potential exceptions that may occur when calling this function."
/home/r4ph/desenv/exception-miner-multi/projects/py/flask/examples/tutorial/flaskr/blog.py,get_post,"def get_post(id, check_author=True):
    """"""Get a post and its author by id.

    Checks that the id exists and optionally that the current user is
    the author.

    :param id: id of post to get
    :param check_author: require the current user to be the author
    :return: the post with author information
    :raise 404: if a post with the given id doesn't exist
    :raise 403: if the current user isn't the author
    """"""
    post = (
        get_db()
        .execute(
            ""SELECT p.id, title, body, created, author_id, username""
            "" FROM post p JOIN user u ON p.author_id = u.id""
            "" WHERE p.id = ?"",
            (id,),
        )
        .fetchone()
    )

    if post is None:
        abort(404, f""Post id {id} doesn't exist."")

    if check_author and post[""author_id""] != g.user[""id""]:
        abort(403)

    return post",,0,0,0,0,0,0,0,0,0,0,,,,0,0,0,,flask,"
Yes, this code needs an exception handling mechanism for the following reasons:

1. `get_db().execute()` can raise a `psycopg2.Error` if there is an error executing the SQL query.
2. `fetchone()` can also raise a `psycopg2.Error` if there is an error fetching the result.
3. The code checks for `None` in the `post` variable, which can be a problem if `get_db().execute()` or `fetchone()` returns `None` instead of raising an exception.
4. The code checks for `post[""author_id""] != g.user[""id""]`, which can raise a `KeyError` if either `post` or `g.user` does not contain the expected key ""id"".
5. The code uses `abort()` to handle errors, but this function does not provide any information about the error that occurred.

To address these issues, the code should include an exception handling mechanism such as a `try-except` block or a decorator that catches and logs exceptions. Additionally, the code should use more robust data structures, such as `Optional[dict]` instead of `dict`, to handle the case where the query returns no results."
/home/r4ph/desenv/exception-miner-multi/projects/py/flask/tests/test_basic.py,normal_index,"def normal_index():
        return ""normal index""",,0,0,0,0,0,0,0,0,0,0,,,,0,0,0,,flask,"
No, this code does not require an exception handling mechanism as it only returns a string value and does not perform any operations that could potentially raise exceptions."
/home/r4ph/desenv/exception-miner-multi/projects/py/flask/src/flask/templating.py,_get_source_fast,"def _get_source_fast(
        self, environment: BaseEnvironment, template: str
    ) -> tuple[str, str | None, t.Callable[[], bool] | None]:
        for _srcobj, loader in self._iter_loaders(template):
            try:
                return loader.get_source(environment, template)
            except TemplateNotFound:
                continue
        raise TemplateNotFound(template)",,1,0,0,0,1,0,0,0,0,1,TemplateNotFound,TemplateNotFound,continue,0,0,0,"def _get_source_fast(
        self, environment: BaseEnvironment, template: str
    ) -> tuple[str, str | None, t.Callable[[], bool] | None]:
        for _srcobj, loader in self._iter_loaders(template):
            return loader.get_source(environment, template)
        raise TemplateNotFound(template)",flask,"
Yes, the code needs an exception handling mechanism because it raises a `TemplateNotFound` exception when no loader is found for the given template name. This could be handled by wrapping the call to `loader.get_source()` in a try-except block and catching the `TemplateNotFound` exception if desired."
/home/r4ph/desenv/exception-miner-multi/projects/py/flask/tests/test_helpers.py,index,"def index():
            def generate():
                yield ""Hello ""
                yield flask.request.args[""name""]
                yield ""!""

            return flask.Response(flask.stream_with_context(Wrapper(generate())))",,0,0,0,0,0,0,0,0,0,0,,,,0,0,0,,flask,"
Yes, this code does require some exception handling mechanisms. The `index()` function calls the `Wrapper` class and passes the generator returned by `generate()` as an argument to the constructor of `Wrapper`. If the `Wrapper` class throws an exception during its initialization, it will be propagated to the caller, which is the `index()` function.

Additionally, the code uses the `flask.request.args[""name""]` attribute inside the generator returned by `generate()`, which can potentially throw a `KeyError` if the ""name"" argument is not present in the request query string.

To handle these potential exceptions, you can wrap the code in a `try-except` block and catch any exception that may be thrown. For example:
```
def index():
    try:
        def generate():
            yield ""Hello ""
            yield flask.request.args[""name""]
            yield ""!""

        return flask.Response(flask.stream_with_context(Wrapper(generate())))
    except Exception as e:
        # handle the exception here
        pass
```
By catching any exception that may be thrown in this way, you can ensure that the code continues to run smoothly even if there are errors or unexpected situations that arise."
/home/r4ph/desenv/exception-miner-multi/projects/py/flask/tests/test_subclassing.py,test_suppressed_exception_logging,"def test_suppressed_exception_logging():
    class SuppressedFlask(flask.Flask):
        def log_exception(self, exc_info):
            pass

    out = StringIO()
    app = SuppressedFlask(__name__)

    @app.route(""/"")
    def index():
        raise Exception(""test"")

    rv = app.test_client().get(""/"", errors_stream=out)
    assert rv.status_code == 500
    assert b""Internal Server Error"" in rv.data
    assert not out.getvalue()",,0,0,0,0,1,1,0,0,0,0,,Exception,,0,0,0,,flask,"
Yes, the code snippet provided needs an exception handling mechanism to handle exceptions that may be raised during the execution of the `index` function. The `raise Exception(""test"")` line in the `@app.route(""/"")` decorator raises an unhandled exception, which causes the Flask application to crash and exit without logging any error information.

To address this issue, you can add a try-except block around the `index` function definition to catch any raised exceptions and log them using the Flask app's logger or by printing them to the console. Here's an example:
```python
from flask import Flask

app = Flask(__name__)

@app.route(""/"")
def index():
    try:
        raise Exception(""test"")
    except Exception as e:
        app.logger.error(f""An exception occurred: {e}"")
        print(f""An exception occurred: {e}"")
```
By adding this exception handling mechanism, the Flask application will log any raised exceptions and continue executing other code that may be defined after the try-except block."
/home/r4ph/desenv/exception-miner-multi/projects/py/flask/src/flask/app.py,test_cli_runner,"def test_cli_runner(self, **kwargs: t.Any) -> FlaskCliRunner:
        """"""Create a CLI runner for testing CLI commands.
        See :ref:`testing-cli`.

        Returns an instance of :attr:`test_cli_runner_class`, by default
        :class:`~flask.testing.FlaskCliRunner`. The Flask app object is
        passed as the first argument.

        .. versionadded:: 1.0
        """"""
        cls = self.test_cli_runner_class

        if cls is None:
            from .testing import FlaskCliRunner as cls

        return cls(self, **kwargs)  # type: ignore",,0,0,0,0,0,0,0,0,0,0,,,,0,0,0,,flask,"
Yes, the code snippet contains an exception handling mechanism. The `test_cli_runner` method has a `try...except` block that catches any exceptions raised during the execution of the `cls` object's constructor. If an exception is raised, it will be caught and passed to the `self.assertRaises` method as a parameter."
/home/r4ph/desenv/exception-miner-multi/projects/py/flask/src/flask/app.py,url_for,"def url_for(
        self,
        /,
        endpoint: str,
        *,
        _anchor: str | None = None,
        _method: str | None = None,
        _scheme: str | None = None,
        _external: bool | None = None,
        **values: t.Any,
    ) -> str:
        """"""Generate a URL to the given endpoint with the given values.

        This is called by :func:`flask.url_for`, and can be called
        directly as well.

        An *endpoint* is the name of a URL rule, usually added with
        :meth:`@app.route() <route>`, and usually the same name as the
        view function. A route defined in a :class:`~flask.Blueprint`
        will prepend the blueprint's name separated by a ``.`` to the
        endpoint.

        In some cases, such as email messages, you want URLs to include
        the scheme and domain, like ``https://example.com/hello``. When
        not in an active request, URLs will be external by default, but
        this requires setting :data:`SERVER_NAME` so Flask knows what
        domain to use. :data:`APPLICATION_ROOT` and
        :data:`PREFERRED_URL_SCHEME` should also be configured as
        needed. This config is only used when not in an active request.

        Functions can be decorated with :meth:`url_defaults` to modify
        keyword arguments before the URL is built.

        If building fails for some reason, such as an unknown endpoint
        or incorrect values, the app's :meth:`handle_url_build_error`
        method is called. If that returns a string, that is returned,
        otherwise a :exc:`~werkzeug.routing.BuildError` is raised.

        :param endpoint: The endpoint name associated with the URL to
            generate. If this starts with a ``.``, the current blueprint
            name (if any) will be used.
        :param _anchor: If given, append this as ``#anchor`` to the URL.
        :param _method: If given, generate the URL associated with this
            method for the endpoint.
        :param _scheme: If given, the URL will have this scheme if it
            is external.
        :param _external: If given, prefer the URL to be internal
            (False) or require it to be external (True). External URLs
            include the scheme and domain. When not in an active
            request, URLs are external by default.
        :param values: Values to use for the variable parts of the URL
            rule. Unknown keys are appended as query string arguments,
            like ``?a=b&c=d``.

        .. versionadded:: 2.2
            Moved from ``flask.url_for``, which calls this method.
        """"""
        req_ctx = _cv_request.get(None)

        if req_ctx is not None:
            url_adapter = req_ctx.url_adapter
            blueprint_name = req_ctx.request.blueprint

            # If the endpoint starts with ""."" and the request matches a
            # blueprint, the endpoint is relative to the blueprint.
            if endpoint[:1] == ""."":
                if blueprint_name is not None:
                    endpoint = f""{blueprint_name}{endpoint}""
                else:
                    endpoint = endpoint[1:]

            # When in a request, generate a URL without scheme and
            # domain by default, unless a scheme is given.
            if _external is None:
                _external = _scheme is not None
        else:
            app_ctx = _cv_app.get(None)

            # If called by helpers.url_for, an app context is active,
            # use its url_adapter. Otherwise, app.url_for was called
            # directly, build an adapter.
            if app_ctx is not None:
                url_adapter = app_ctx.url_adapter
            else:
                url_adapter = self.create_url_adapter(None)

            if url_adapter is None:
                raise RuntimeError(
                    ""Unable to build URLs outside an active request""
                    "" without 'SERVER_NAME' configured. Also configure""
                    "" 'APPLICATION_ROOT' and 'PREFERRED_URL_SCHEME' as""
                    "" needed.""
                )

            # When outside a request, generate a URL with scheme and
            # domain by default.
            if _external is None:
                _external = True

        # It is an error to set _scheme when _external=False, in order
        # to avoid accidental insecure URLs.
        if _scheme is not None and not _external:
            raise ValueError(""When specifying '_scheme', '_external' must be True."")

        self.inject_url_defaults(endpoint, values)

        try:
            rv = url_adapter.build(  # type: ignore[union-attr]
                endpoint,
                values,
                method=_method,
                url_scheme=_scheme,
                force_external=_external,
            )
        except BuildError as error:
            values.update(
                _anchor=_anchor, _method=_method, _scheme=_scheme, _external=_external
            )
            return self.handle_url_build_error(error, endpoint, values)

        if _anchor is not None:
            _anchor = _url_quote(_anchor, safe=""%!#$&'()*+,/:;=?@"")
            rv = f""{rv}#{_anchor}""

        return rv",,1,0,0,0,2,0,0,0,0,0,BuildError,RuntimeError ValueError,"values.update(
                _anchor=_anchor, _method=_method, _scheme=_scheme, _external=_external
            )
            return self.handle_url_build_error(error, endpoint, values)",0,0,0,"def url_for(
        self,
        /,
        endpoint: str,
        *,
        _anchor: str | None = None,
        _method: str | None = None,
        _scheme: str | None = None,
        _external: bool | None = None,
        **values: t.Any,
    ) -> str:
        """"""Generate a URL to the given endpoint with the given values.

        This is called by :func:`flask.url_for`, and can be called
        directly as well.

        An *endpoint* is the name of a URL rule, usually added with
        :meth:`@app.route() <route>`, and usually the same name as the
        view function. A route defined in a :class:`~flask.Blueprint`
        will prepend the blueprint's name separated by a ``.`` to the
        endpoint.

        In some cases, such as email messages, you want URLs to include
        the scheme and domain, like ``https://example.com/hello``. When
        not in an active request, URLs will be external by default, but
        this requires setting :data:`SERVER_NAME` so Flask knows what
        domain to use. :data:`APPLICATION_ROOT` and
        :data:`PREFERRED_URL_SCHEME` should also be configured as
        needed. This config is only used when not in an active request.

        Functions can be decorated with :meth:`url_defaults` to modify
        keyword arguments before the URL is built.

        If building fails for some reason, such as an unknown endpoint
        or incorrect values, the app's :meth:`handle_url_build_error`
        method is called. If that returns a string, that is returned,
        otherwise a :exc:`~werkzeug.routing.BuildError` is raised.

        :param endpoint: The endpoint name associated with the URL to
            generate. If this starts with a ``.``, the current blueprint
            name (if any) will be used.
        :param _anchor: If given, append this as ``#anchor`` to the URL.
        :param _method: If given, generate the URL associated with this
            method for the endpoint.
        :param _scheme: If given, the URL will have this scheme if it
            is external.
        :param _external: If given, prefer the URL to be internal
            (False) or require it to be external (True). External URLs
            include the scheme and domain. When not in an active
            request, URLs are external by default.
        :param values: Values to use for the variable parts of the URL
            rule. Unknown keys are appended as query string arguments,
            like ``?a=b&c=d``.

        .. versionadded:: 2.2
            Moved from ``flask.url_for``, which calls this method.
        """"""
        req_ctx = _cv_request.get(None)

        if req_ctx is not None:
            url_adapter = req_ctx.url_adapter
            blueprint_name = req_ctx.request.blueprint

            # If the endpoint starts with ""."" and the request matches a
            # blueprint, the endpoint is relative to the blueprint.
            if endpoint[:1] == ""."":
                if blueprint_name is not None:
                    endpoint = f""{blueprint_name}{endpoint}""
                else:
                    endpoint = endpoint[1:]

            # When in a request, generate a URL without scheme and
            # domain by default, unless a scheme is given.
            if _external is None:
                _external = _scheme is not None
        else:
            app_ctx = _cv_app.get(None)

            # If called by helpers.url_for, an app context is active,
            # use its url_adapter. Otherwise, app.url_for was called
            # directly, build an adapter.
            if app_ctx is not None:
                url_adapter = app_ctx.url_adapter
            else:
                url_adapter = self.create_url_adapter(None)

            if url_adapter is None:
                raise RuntimeError(
                    ""Unable to build URLs outside an active request""
                    "" without 'SERVER_NAME' configured. Also configure""
                    "" 'APPLICATION_ROOT' and 'PREFERRED_URL_SCHEME' as""
                    "" needed.""
                )

            # When outside a request, generate a URL with scheme and
            # domain by default.
            if _external is None:
                _external = True

        # It is an error to set _scheme when _external=False, in order
        # to avoid accidental insecure URLs.
        if _scheme is not None and not _external:
            raise ValueError(""When specifying '_scheme', '_external' must be True."")

        self.inject_url_defaults(endpoint, values)

        rv = url_adapter.build(  # type: ignore[union-attr]
                endpoint,
                values,
                method=_method,
                url_scheme=_scheme,
                force_external=_external,
            )

        if _anchor is not None:
            _anchor = _url_quote(_anchor, safe=""%!#$&'()*+,/:;=?@"")
            rv = f""{rv}#{_anchor}""

        return rv",flask,"
Yes, the code needs an exception handling mechanism to handle unexpected errors that may occur during the generation of URLs using the `url_for` method. The method calls several other methods internally, including `inject_url_defaults`, which can raise exceptions if the endpoint is not found or the values provided are invalid. Additionally, the `build` method of the `url_adapter` object used in the code raises a `BuildError` exception when it fails to build the URL due to an unknown endpoint or incorrect values. Therefore, it is important to wrap the code in a try-except block to handle these potential exceptions and return meaningful error messages to the user."
/home/r4ph/desenv/exception-miner-multi/projects/py/flask/examples/tutorial/flaskr/__init__.py,create_app,"def create_app(test_config=None):
    """"""Create and configure an instance of the Flask application.""""""
    app = Flask(__name__, instance_relative_config=True)
    app.config.from_mapping(
        # a default secret that should be overridden by instance config
        SECRET_KEY=""dev"",
        # store the database in the instance folder
        DATABASE=os.path.join(app.instance_path, ""flaskr.sqlite""),
    )

    if test_config is None:
        # load the instance config, if it exists, when not testing
        app.config.from_pyfile(""config.py"", silent=True)
    else:
        # load the test config if passed in
        app.config.update(test_config)

    # ensure the instance folder exists
    try:
        os.makedirs(app.instance_path)
    except OSError:
        pass

    @app.route(""/hello"")
    def hello():
        return ""Hello, World!""

    # register the database commands
    from . import db

    db.init_app(app)

    # apply the blueprints to the app
    from . import auth
    from . import blog

    app.register_blueprint(auth.bp)
    app.register_blueprint(blog.bp)

    # make url_for('index') == url_for('blog.index')
    # in another app, you might define a separate main index here with
    # app.route, while giving the blog blueprint a url_prefix, but for
    # the tutorial the blog will be the main index
    app.add_url_rule(""/"", endpoint=""index"")

    return app",,1,1,0,0,0,0,0,0,0,0,OSError,,pass,0,0,0,"def create_app(test_config=None):
    """"""Create and configure an instance of the Flask application.""""""
    app = Flask(__name__, instance_relative_config=True)
    app.config.from_mapping(
        # a default secret that should be overridden by instance config
        SECRET_KEY=""dev"",
        # store the database in the instance folder
        DATABASE=os.path.join(app.instance_path, ""flaskr.sqlite""),
    )

    if test_config is None:
        # load the instance config, if it exists, when not testing
        app.config.from_pyfile(""config.py"", silent=True)
    else:
        # load the test config if passed in
        app.config.update(test_config)

    # ensure the instance folder exists
    os.makedirs(app.instance_path)

    @app.route(""/hello"")
    def hello():
        return ""Hello, World!""

    # register the database commands
    from . import db

    db.init_app(app)

    # apply the blueprints to the app
    from . import auth
    from . import blog

    app.register_blueprint(auth.bp)
    app.register_blueprint(blog.bp)

    # make url_for('index') == url_for('blog.index')
    # in another app, you might define a separate main index here with
    # app.route, while giving the blog blueprint a url_prefix, but for
    # the tutorial the blog will be the main index
    app.add_url_rule(""/"", endpoint=""index"")

    return app",flask,"
Yes, this code needs an exception handling mechanism. The `create_app()` function is responsible for creating and configuring the Flask application, but it does not include any error handling or logging mechanisms. If an error occurs during the creation of the app, such as a database connection failure or a syntax error in the configuration file, the code will simply raise an exception without providing any information about what went wrong.

To address this issue, you could add a `try...except` block to catch any errors that may occur during the creation of the app and provide more detailed information about the error. Additionally, you could also consider adding logging mechanisms to keep track of any errors that occur during the execution of the app."
/home/r4ph/desenv/exception-miner-multi/projects/py/flask/tests/test_json.py,index,"def index():
        return flask.jsonify(value=value)",,0,0,0,0,0,0,0,0,0,0,,,,0,0,0,,flask,"
No, this code does not need an exception handling mechanism. The `return` statement in the `index()` function is returning a JSON object, which is a valid response for an HTTP request. If any errors occur during the execution of the function, they will be caught and handled by Flask's built-in error handling mechanisms."
/home/r4ph/desenv/exception-miner-multi/projects/py/flask/src/flask/config.py,from_prefixed_env,"def from_prefixed_env(
        self, prefix: str = ""FLASK"", *, loads: t.Callable[[str], t.Any] = json.loads
    ) -> bool:
        """"""Load any environment variables that start with ``FLASK_``,
        dropping the prefix from the env key for the config key. Values
        are passed through a loading function to attempt to convert them
        to more specific types than strings.

        Keys are loaded in :func:`sorted` order.

        The default loading function attempts to parse values as any
        valid JSON type, including dicts and lists.

        Specific items in nested dicts can be set by separating the
        keys with double underscores (``__``). If an intermediate key
        doesn't exist, it will be initialized to an empty dict.

        :param prefix: Load env vars that start with this prefix,
            separated with an underscore (``_``).
        :param loads: Pass each string value to this function and use
            the returned value as the config value. If any error is
            raised it is ignored and the value remains a string. The
            default is :func:`json.loads`.

        .. versionadded:: 2.1
        """"""
        prefix = f""{prefix}_""
        len_prefix = len(prefix)

        for key in sorted(os.environ):
            if not key.startswith(prefix):
                continue

            value = os.environ[key]

            try:
                value = loads(value)
            except Exception:
                # Keep the value as a string if loading failed.
                pass

            # Change to key.removeprefix(prefix) on Python >= 3.9.
            key = key[len_prefix:]

            if ""__"" not in key:
                # A non-nested key, set directly.
                self[key] = value
                continue

            # Traverse nested dictionaries with keys separated by ""__"".
            current = self
            *parts, tail = key.split(""__"")

            for part in parts:
                # If an intermediate dict does not exist, create it.
                if part not in current:
                    current[part] = {}

                current = current[part]

            current[tail] = value

        return True",,1,1,0,1,0,0,0,0,0,0,Exception,,pass,0,0,0,"def from_prefixed_env(
        self, prefix: str = ""FLASK"", *, loads: t.Callable[[str], t.Any] = json.loads
    ) -> bool:
        """"""Load any environment variables that start with ``FLASK_``,
        dropping the prefix from the env key for the config key. Values
        are passed through a loading function to attempt to convert them
        to more specific types than strings.

        Keys are loaded in :func:`sorted` order.

        The default loading function attempts to parse values as any
        valid JSON type, including dicts and lists.

        Specific items in nested dicts can be set by separating the
        keys with double underscores (``__``). If an intermediate key
        doesn't exist, it will be initialized to an empty dict.

        :param prefix: Load env vars that start with this prefix,
            separated with an underscore (``_``).
        :param loads: Pass each string value to this function and use
            the returned value as the config value. If any error is
            raised it is ignored and the value remains a string. The
            default is :func:`json.loads`.

        .. versionadded:: 2.1
        """"""
        prefix = f""{prefix}_""
        len_prefix = len(prefix)

        for key in sorted(os.environ):
            if not key.startswith(prefix):
                continue

            value = os.environ[key]

            value = loads(value)

            # Change to key.removeprefix(prefix) on Python >= 3.9.
            key = key[len_prefix:]

            if ""__"" not in key:
                # A non-nested key, set directly.
                self[key] = value
                continue

            # Traverse nested dictionaries with keys separated by ""__"".
            current = self
            *parts, tail = key.split(""__"")

            for part in parts:
                # If an intermediate dict does not exist, create it.
                if part not in current:
                    current[part] = {}

                current = current[part]

            current[tail] = value

        return True",flask,"
Yes, this code needs an exception handling mechanism because the `loads` function that is passed as a parameter can raise exceptions during its execution. The default `loads` function used in the code is `json.loads`, which can raise exceptions if the string value passed to it cannot be parsed as JSON. Therefore, any code that uses this function should handle these exceptions appropriately to avoid breaking the program flow."
/home/r4ph/desenv/exception-miner-multi/projects/py/flask/tests/test_blueprints.py,test_blueprint_app_error_handling,"def test_blueprint_app_error_handling(app, client):
    errors = flask.Blueprint(""errors"", __name__)

    @errors.app_errorhandler(403)
    def forbidden_handler(e):
        return ""you shall not pass"", 403

    @app.route(""/forbidden"")
    def app_forbidden():
        flask.abort(403)

    forbidden_bp = flask.Blueprint(""forbidden_bp"", __name__)

    @forbidden_bp.route(""/nope"")
    def bp_forbidden():
        flask.abort(403)

    app.register_blueprint(errors)
    app.register_blueprint(forbidden_bp)

    assert client.get(""/forbidden"").data == b""you shall not pass""
    assert client.get(""/nope"").data == b""you shall not pass""",,0,0,0,0,0,0,0,0,0,0,,,,0,0,0,,flask,"
Yes, the code needs an exception handling mechanism. The `forbidden_handler` function is defined as an error handler for HTTP status code 403, but it does not catch any exceptions that may occur during its execution. This means that if there is an uncaught exception within the function, it will propagate up to the parent context and result in a crash of the Flask application.

To fix this issue, you can add a `try`/`except` block around the code that may raise exceptions, like so:
```
@errors.app_errorhandler(403)
def forbidden_handler(e):
    try:
        # Your code here
    except Exception as e:
        print(""An exception occurred:"", e)
        return ""you shall not pass"", 500
```
By doing this, you are catching any exceptions that may occur during the execution of the `forbidden_handler` function and returning a 500 Internal Server Error response instead. This will prevent the Flask application from crashing and allow it to continue running smoothly."
/home/r4ph/desenv/exception-miner-multi/projects/py/flask/tests/test_helpers.py,gen,"def gen():
                yield flask.session[""test""]",,0,0,0,0,0,0,0,0,0,0,,,,0,0,0,,flask,"
Yes. The `gen` function does not have any explicit exception handling mechanism, and it could potentially raise a `KeyError` if the `flask.session[""test""]` key is not found in the session dictionary. Therefore, it would be best to add some form of exception handling to ensure that the code can handle such errors gracefully."
/home/r4ph/desenv/exception-miner-multi/projects/py/flask/tests/test_appctx.py,cleanup,"def cleanup(exception):
        cleanup_stuff.append(exception)",,0,0,0,0,0,0,0,0,0,0,,,,0,0,0,,flask,"
Yes, the provided code snippet requires an exception handling mechanism because it defines a function named `cleanup` that takes an argument of type `exception`. This means that the function may raise an exception during its execution, and it is important to handle such exceptions in order to prevent them from causing issues in the program's flow.

Additionally, the use of the `.append()` method on a list named `cleanup_stuff` suggests that the intention of this code snippet is to collect exceptions that may be raised during cleanup operations. Therefore, it is necessary to handle any potential exceptions that may be raised by the `cleanup` function in order to ensure that the program's state remains consistent and predictable."
/home/r4ph/desenv/exception-miner-multi/projects/py/flask/tests/test_basic.py,test_get_method_on_g,"def test_get_method_on_g(app_ctx):
    assert flask.g.get(""x"") is None
    assert flask.g.get(""x"", 11) == 11
    flask.g.x = 42
    assert flask.g.get(""x"") == 42
    assert flask.g.x == 42",,0,0,0,0,0,0,0,0,0,0,,,,0,0,0,,flask,"
Yes, this code needs an exception handling mechanism because it is using the `get` method of the `flask.g` object, which can raise a `KeyError` if the specified key does not exist. Therefore, the code should include a try-except block to handle the case where the key does not exist.

Here is an example of how the code could be modified to include exception handling:
```
def test_get_method_on_g(app_ctx):
    try:
        assert flask.g.get(""x"") is None
    except KeyError:
        print(""The key 'x' does not exist in the global object."")
    assert flask.g.get(""x"", 11) == 11
    flask.g.x = 42
    try:
        assert flask.g.get(""x"") == 42
    except KeyError:
        print(""The key 'x' does not exist in the global object."")
    assert flask.g.x == 42
```"
/home/r4ph/desenv/exception-miner-multi/projects/py/flask/tests/test_appctx.py,test_basic_url_generation,"def test_basic_url_generation(app):
    app.config[""SERVER_NAME""] = ""localhost""
    app.config[""PREFERRED_URL_SCHEME""] = ""https""

    @app.route(""/"")
    def index():
        pass

    with app.app_context():
        rv = flask.url_for(""index"")
        assert rv == ""https://localhost/""",,0,0,0,0,0,0,0,0,0,0,,,,0,0,0,,flask,"
Yes, the provided code needs an exception handling mechanism. The `with` block used to create the app context may raise an error if the configuration file is not found or cannot be loaded. Additionally, the `flask.url_for()` function may also raise an error if it fails to generate the URL. Therefore, it is important to handle these potential errors and provide appropriate handling mechanisms to prevent the program from crashing."
/home/r4ph/desenv/exception-miner-multi/projects/py/flask/src/flask/helpers.py,get_root_path,"def get_root_path(import_name: str) -> str:
    """"""Find the root path of a package, or the path that contains a
    module. If it cannot be found, returns the current working
    directory.

    Not to be confused with the value returned by :func:`find_package`.

    :meta private:
    """"""
    # Module already imported and has a file attribute. Use that first.
    mod = sys.modules.get(import_name)

    if mod is not None and hasattr(mod, ""__file__"") and mod.__file__ is not None:
        return os.path.dirname(os.path.abspath(mod.__file__))

    # Next attempt: check the loader.
    try:
        spec = importlib.util.find_spec(import_name)

        if spec is None:
            raise ValueError
    except (ImportError, ValueError):
        loader = None
    else:
        loader = spec.loader

    # Loader does not exist or we're referring to an unloaded main
    # module or a main module without path (interactive sessions), go
    # with the current working directory.
    if loader is None:
        return os.getcwd()

    if hasattr(loader, ""get_filename""):
        filepath = loader.get_filename(import_name)
    else:
        # Fall back to imports.
        __import__(import_name)
        mod = sys.modules[import_name]
        filepath = getattr(mod, ""__file__"", None)

        # If we don't have a file path it might be because it is a
        # namespace package. In this case pick the root path from the
        # first module that is contained in the package.
        if filepath is None:
            raise RuntimeError(
                ""No root path can be found for the provided module""
                f"" {import_name!r}. This can happen because the module""
                "" came from an import hook that does not provide file""
                "" name information or because it's a namespace package.""
                "" In this case the root path needs to be explicitly""
                "" provided.""
            )

    # filepath is import_name.py for a module, or __init__.py for a package.
    return os.path.dirname(os.path.abspath(filepath))  # type: ignore[no-any-return]",,1,0,0,0,2,0,0,0,1,0,ImportError ValueError,ValueError RuntimeError,loader = None,0,0,0,"def get_root_path(import_name: str) -> str:
    """"""Find the root path of a package, or the path that contains a
    module. If it cannot be found, returns the current working
    directory.

    Not to be confused with the value returned by :func:`find_package`.

    :meta private:
    """"""
    # Module already imported and has a file attribute. Use that first.
    mod = sys.modules.get(import_name)

    if mod is not None and hasattr(mod, ""__file__"") and mod.__file__ is not None:
        return os.path.dirname(os.path.abspath(mod.__file__))

    # Next attempt: check the loader.
    spec = importlib.util.find_spec(import_name)

        if spec is None:
            raise ValueError

    # Loader does not exist or we're referring to an unloaded main
    # module or a main module without path (interactive sessions), go
    # with the current working directory.
    if loader is None:
        return os.getcwd()

    if hasattr(loader, ""get_filename""):
        filepath = loader.get_filename(import_name)
    else:
        # Fall back to imports.
        __import__(import_name)
        mod = sys.modules[import_name]
        filepath = getattr(mod, ""__file__"", None)

        # If we don't have a file path it might be because it is a
        # namespace package. In this case pick the root path from the
        # first module that is contained in the package.
        if filepath is None:
            raise RuntimeError(
                ""No root path can be found for the provided module""
                f"" {import_name!r}. This can happen because the module""
                "" came from an import hook that does not provide file""
                "" name information or because it's a namespace package.""
                "" In this case the root path needs to be explicitly""
                "" provided.""
            )

    # filepath is import_name.py for a module, or __init__.py for a package.
    return os.path.dirname(os.path.abspath(filepath))  # type: ignore[no-any-return]",flask,"
Yes, this code needs an exception handling mechanism. The `ValueError` that can be raised by the `importlib.util.find_spec()` function is not properly handled in the code. The code also uses `sys.modules.get(import_name)` to retrieve a module object and then checks if it has the `__file__` attribute, but this can also raise a `KeyError`. Additionally, the code assumes that the `loader` attribute of the `spec` object is not `None`, but this can also be `None`. Therefore, the code needs to handle these exceptions properly in order to ensure robustness and prevent unexpected behavior."
/home/r4ph/desenv/exception-miner-multi/projects/py/flask/src/flask/sansio/scaffold.py,add_url_rule,"def add_url_rule(
        self,
        rule: str,
        endpoint: str | None = None,
        view_func: ft.RouteCallable | None = None,
        provide_automatic_options: bool | None = None,
        **options: t.Any,
    ) -> None:
        """"""Register a rule for routing incoming requests and building
        URLs. The :meth:`route` decorator is a shortcut to call this
        with the ``view_func`` argument. These are equivalent:

        .. code-block:: python

            @app.route(""/"")
            def index():
                ...

        .. code-block:: python

            def index():
                ...

            app.add_url_rule(""/"", view_func=index)

        See :ref:`url-route-registrations`.

        The endpoint name for the route defaults to the name of the view
        function if the ``endpoint`` parameter isn't passed. An error
        will be raised if a function has already been registered for the
        endpoint.

        The ``methods`` parameter defaults to ``[""GET""]``. ``HEAD`` is
        always added automatically, and ``OPTIONS`` is added
        automatically by default.

        ``view_func`` does not necessarily need to be passed, but if the
        rule should participate in routing an endpoint name must be
        associated with a view function at some point with the
        :meth:`endpoint` decorator.

        .. code-block:: python

            app.add_url_rule(""/"", endpoint=""index"")

            @app.endpoint(""index"")
            def index():
                ...

        If ``view_func`` has a ``required_methods`` attribute, those
        methods are added to the passed and automatic methods. If it
        has a ``provide_automatic_methods`` attribute, it is used as the
        default if the parameter is not passed.

        :param rule: The URL rule string.
        :param endpoint: The endpoint name to associate with the rule
            and view function. Used when routing and building URLs.
            Defaults to ``view_func.__name__``.
        :param view_func: The view function to associate with the
            endpoint name.
        :param provide_automatic_options: Add the ``OPTIONS`` method and
            respond to ``OPTIONS`` requests automatically.
        :param options: Extra options passed to the
            :class:`~werkzeug.routing.Rule` object.
        """"""
        raise NotImplementedError",,0,0,0,0,1,0,0,0,0,0,,NotImplementedError,,0,0,0,,flask,"
Yes, the `add_url_rule` method in Flask's `BaseApp` class raises a `NotImplementedError` if it is called directly. This means that any subclass of `BaseApp` must implement its own version of this method and handle any exceptions that may be raised during its execution."
/home/r4ph/desenv/exception-miner-multi/projects/py/flask/src/flask/cli.py,load_dotenv,"def load_dotenv(path: str | os.PathLike[str] | None = None) -> bool:
    """"""Load ""dotenv"" files in order of precedence to set environment variables.

    If an env var is already set it is not overwritten, so earlier files in the
    list are preferred over later files.

    This is a no-op if `python-dotenv`_ is not installed.

    .. _python-dotenv: https://github.com/theskumar/python-dotenv#readme

    :param path: Load the file at this location instead of searching.
    :return: ``True`` if a file was loaded.

    .. versionchanged:: 2.0
        The current directory is not changed to the location of the
        loaded file.

    .. versionchanged:: 2.0
        When loading the env files, set the default encoding to UTF-8.

    .. versionchanged:: 1.1.0
        Returns ``False`` when python-dotenv is not installed, or when
        the given path isn't a file.

    .. versionadded:: 1.0
    """"""
    try:
        import dotenv
    except ImportError:
        if path or os.path.isfile("".env"") or os.path.isfile("".flaskenv""):
            click.secho(
                "" * Tip: There are .env or .flaskenv files present.""
                ' Do ""pip install python-dotenv"" to use them.',
                fg=""yellow"",
                err=True,
            )

        return False

    # Always return after attempting to load a given path, don't load
    # the default files.
    if path is not None:
        if os.path.isfile(path):
            return dotenv.load_dotenv(path, encoding=""utf-8"")

        return False

    loaded = False

    for name in ("".env"", "".flaskenv""):
        path = dotenv.find_dotenv(name, usecwd=True)

        if not path:
            continue

        dotenv.load_dotenv(path, encoding=""utf-8"")
        loaded = True

    return loaded  # True if at least one file was located and loaded.",,1,0,0,0,0,0,0,0,0,0,ImportError,,"if path or os.path.isfile("".env"") or os.path.isfile("".flaskenv""):
            click.secho(
                "" * Tip: There are .env or .flaskenv files present.""
                ' Do ""pip install python-dotenv"" to use them.',
                fg=""yellow"",
                err=True,
            )

        return False",0,0,0,"def load_dotenv(path: str | os.PathLike[str] | None = None) -> bool:
    """"""Load ""dotenv"" files in order of precedence to set environment variables.

    If an env var is already set it is not overwritten, so earlier files in the
    list are preferred over later files.

    This is a no-op if `python-dotenv`_ is not installed.

    .. _python-dotenv: https://github.com/theskumar/python-dotenv#readme

    :param path: Load the file at this location instead of searching.
    :return: ``True`` if a file was loaded.

    .. versionchanged:: 2.0
        The current directory is not changed to the location of the
        loaded file.

    .. versionchanged:: 2.0
        When loading the env files, set the default encoding to UTF-8.

    .. versionchanged:: 1.1.0
        Returns ``False`` when python-dotenv is not installed, or when
        the given path isn't a file.

    .. versionadded:: 1.0
    """"""
    import dotenv

    # Always return after attempting to load a given path, don't load
    # the default files.
    if path is not None:
        if os.path.isfile(path):
            return dotenv.load_dotenv(path, encoding=""utf-8"")

        return False

    loaded = False

    for name in ("".env"", "".flaskenv""):
        path = dotenv.find_dotenv(name, usecwd=True)

        if not path:
            continue

        dotenv.load_dotenv(path, encoding=""utf-8"")
        loaded = True

    return loaded  # True if at least one file was located and loaded.",flask,"
Yes, this code needs exception handling mechanism as it is using third-party library `dotenv` which may raise exceptions while loading files. The function `load_dotenv` returns a boolean value indicating whether a file was loaded, but if an error occurs during the loading process, it will not be caught and raised to the caller. Therefore, the function should include appropriate exception handling mechanism to handle such errors and provide meaningful information to the user."
/home/r4ph/desenv/exception-miner-multi/projects/py/flask/src/flask/debughelpers.py,__getitem__,"def __getitem__(self, key: str) -> t.Any:
            try:
                return super().__getitem__(key)
            except KeyError as e:
                if key not in request.form:
                    raise

                raise DebugFilesKeyError(request, key).with_traceback(
                    e.__traceback__
                ) from None",,1,0,0,0,2,0,0,0,0,1,KeyError,,"if key not in request.form:
                    raise

                raise DebugFilesKeyError(request, key).with_traceback(
                    e.__traceback__
                ) from None",0,0,0,"def __getitem__(self, key: str) -> t.Any:
            return super().__getitem__(key)",flask,"
No, this code does not require an exception handling mechanism. The `__getitem__` method is defined as returning `Any`, which means that it can return any type of value, including None. Therefore, there is no need to handle potential exceptions in the code."
/home/r4ph/desenv/exception-miner-multi/projects/py/flask/tests/test_basic.py,teardown_request1,"def teardown_request1(exc):
        assert type(exc) is ZeroDivisionError
        called.append(True)
        # This raises a new error and blows away sys.exc_info(), so we can
        # test that all teardown_requests get passed the same original
        # exception.
        try:
            raise TypeError()
        except Exception:
            pass",,1,1,0,1,1,0,0,0,0,0,Exception,TypeError,pass,0,0,0,"def teardown_request1(exc):
        assert type(exc) is ZeroDivisionError
        called.append(True)
        # This raises a new error and blows away sys.exc_info(), so we can
        # test that all teardown_requests get passed the same original
        # exception.
        raise TypeError()",flask,"
Yes, this code needs an exception handling mechanism. The `teardown_request1` function defines its own custom error handler using the `except` block. This is not the recommended way to handle errors in Python, as it can lead to confusion and make the code harder to debug. Instead, you should use a try-except block to catch any exceptions that may be raised by the function, and then handle them appropriately."
/home/r4ph/desenv/exception-miner-multi/projects/py/flask/tests/test_views.py,test_init_once,"def test_init_once(app, client):
    n = 0

    class CountInit(flask.views.View):
        init_every_request = False

        def __init__(self):
            nonlocal n
            n += 1

        def dispatch_request(self):
            return str(n)

    app.add_url_rule(""/"", view_func=CountInit.as_view(""index""))
    assert client.get(""/"").data == b""1""
    assert client.get(""/"").data == b""1""",,0,0,0,0,0,0,0,0,0,0,,,,0,0,0,,flask,"
Yes, this code needs an exception handling mechanism. The `CountInit` class is inheriting from `flask.views.View`, which means it has the ability to handle exceptions through the `dispatch_request` method. However, the `__init__` method does not have any exception handling mechanism, and if an exception were to occur during initialization of the `CountInit` object, it would propagate up to the calling code without being handled.

Additionally, since the `n` variable is declared as a global variable in the `__init__` method, if another request comes in while the first request is still being processed, the second request may also try to access the same `n` variable, which could lead to race conditions and unpredictable behavior.

Therefore, it is recommended to add exception handling mechanisms to both the `__init__` method and the `dispatch_request` method to ensure that any exceptions that occur during initialization or request processing are handled properly."
/home/r4ph/desenv/exception-miner-multi/projects/py/flask/tests/test_basic.py,before1,"def before1():
        called.append(1)",,0,0,0,0,0,0,0,0,0,0,,,,0,0,0,,flask,"
No, this code does not require an exception handling mechanism. The `called` list is created within the function and it will automatically be garbage collected when the function returns. So, there is no need to worry about any exceptions related to memory management."
/home/r4ph/desenv/exception-miner-multi/projects/py/flask/tests/test_reqctx.py,test_teardown_with_previous_exception,"def test_teardown_with_previous_exception(app):
    buffer = []

    @app.teardown_request
    def end_of_request(exception):
        buffer.append(exception)

    try:
        raise Exception(""dummy"")
    except Exception:
        pass

    with app.test_request_context():
        assert buffer == []
    assert buffer == [None]",,1,1,0,1,1,1,0,0,0,0,Exception,Exception,pass,0,0,0,"def test_teardown_with_previous_exception(app):
    buffer = []

    @app.teardown_request
    def end_of_request(exception):
        buffer.append(exception)

    raise Exception(""dummy"")

    with app.test_request_context():
        assert buffer == []
    assert buffer == [None]",flask,"
Yes, this code needs an exception handling mechanism because it raises an `Exception` in the `test_teardown_with_previous_exception` function and does not catch it. If an exception is raised inside a decorator without being caught, it will propagate up to the caller and potentially cause a crash or other unexpected behavior.

In this specific case, the code is raising an exception inside the `@app.teardown_request` decorator, which means that if the `end_of_request` function is called with an exception as its argument, it will not be caught by any exception handling mechanism and will propagate up to the caller.

Therefore, the code should include a `try...except` block or use a different way of handling exceptions inside the decorator, such as using `app.handle_exception` method, to ensure that the exception is properly handled and does not cause any issues in the application."
/home/r4ph/desenv/exception-miner-multi/projects/py/flask/tests/test_reqctx.py,test_teardown_with_handled_exception,"def test_teardown_with_handled_exception(app):
    buffer = []

    @app.teardown_request
    def end_of_request(exception):
        buffer.append(exception)

    with app.test_request_context():
        assert buffer == []
        try:
            raise Exception(""dummy"")
        except Exception:
            pass
    assert buffer == [None]",,1,1,0,1,1,1,0,0,0,0,Exception,Exception,pass,0,0,0,"def test_teardown_with_handled_exception(app):
    buffer = []

    @app.teardown_request
    def end_of_request(exception):
        buffer.append(exception)

    with app.test_request_context():
        assert buffer == []
        raise Exception(""dummy"")
    assert buffer == [None]",flask,"
Yes, the provided code requires exception handling mechanism. The `test_teardown_with_handled_exception` function defines a teardown handler using the `@app.teardown_request` decorator. This means that if an exception is raised during the request processing, it will be handled by the teardown handler and stored in the `buffer` list.

However, in the second line of the code snippet, we can see that a dummy exception is raised using the `raise Exception(""dummy"")` statement. This means that the teardown handler will receive an actual exception object as its argument, which it will then store in the `buffer` list.

Therefore, the provided code needs to have some mechanism for handling exceptions raised during request processing. One possible solution is to catch the exception inside the teardown handler and handle it appropriately, such as logging it or returning a 500 Internal Server Error response."
/home/r4ph/desenv/exception-miner-multi/projects/py/flask/tests/test_cli.py,dotenv_not_available,"def dotenv_not_available():
    try:
        import dotenv  # noqa: F401
    except ImportError:
        return True

    return False",,1,0,0,0,0,0,0,0,0,0,ImportError,,return True,0,0,0,"def dotenv_not_available():
    import dotenv  # noqa: F401

    return False",flask,"
Yes, this code snippet needs an exception handling mechanism because it imports a module (`dotenv`) that may not be available in all environments. The `noqa` comment is used to suppress the error that would occur if the module is not found, but it does not provide any mechanism for handling the error gracefully.

To handle this situation, you can add a try-except block around the import statement and catch the `ImportError` exception that will be raised if the module is not available:
```python
try:
    import dotenv  # noqa: F401
except ImportError:
    pass
```
By doing this, you can ensure that the code continues to execute even if the `dotenv` module is not available in the current environment."
/home/r4ph/desenv/exception-miner-multi/projects/py/flask/examples/tutorial/flaskr/blog.py,update,"def update(id):
    """"""Update a post if the current user is the author.""""""
    post = get_post(id)

    if request.method == ""POST"":
        title = request.form[""title""]
        body = request.form[""body""]
        error = None

        if not title:
            error = ""Title is required.""

        if error is not None:
            flash(error)
        else:
            db = get_db()
            db.execute(
                ""UPDATE post SET title = ?, body = ? WHERE id = ?"", (title, body, id)
            )
            db.commit()
            return redirect(url_for(""blog.index""))

    return render_template(""blog/update.html"", post=post)",,0,0,0,0,0,0,0,0,0,0,,,,0,0,0,,flask,"
Yes, this code needs an exception handling mechanism. The `get_post` function is called without any error handling, which means that if there is an error in the query, it will raise an exception and the rest of the code will not be executed. This can lead to unexpected behavior and errors. To fix this issue, you should add try-except block around the call to `get_post` function and handle any exceptions that may occur. Additionally, you can also use a context manager to open the database connection in a safe way."
/home/r4ph/desenv/exception-miner-multi/projects/py/flask/src/flask/app.py,async_to_sync,"def async_to_sync(
        self, func: t.Callable[..., t.Coroutine[t.Any, t.Any, t.Any]]
    ) -> t.Callable[..., t.Any]:
        """"""Return a sync function that will run the coroutine function.

        .. code-block:: python

            result = app.async_to_sync(func)(*args, **kwargs)

        Override this method to change how the app converts async code
        to be synchronously callable.

        .. versionadded:: 2.0
        """"""
        try:
            from asgiref.sync import async_to_sync as asgiref_async_to_sync
        except ImportError:
            raise RuntimeError(
                ""Install Flask with the 'async' extra in order to use async views.""
            ) from None

        return asgiref_async_to_sync(func)",,1,0,0,0,1,0,0,0,0,0,ImportError,RuntimeError,"raise RuntimeError(
                ""Install Flask with the 'async' extra in order to use async views.""
            ) from None",0,0,0,"def async_to_sync(
        self, func: t.Callable[..., t.Coroutine[t.Any, t.Any, t.Any]]
    ) -> t.Callable[..., t.Any]:
        """"""Return a sync function that will run the coroutine function.

        .. code-block:: python

            result = app.async_to_sync(func)(*args, **kwargs)

        Override this method to change how the app converts async code
        to be synchronously callable.

        .. versionadded:: 2.0
        """"""
        from asgiref.sync import async_to_sync as asgiref_async_to_sync

        return asgiref_async_to_sync(func)",flask,"
Yes, the code snippet provided contains a try-except block that handles any exceptions raised by the `asgiref_async_to_sync` function. The except block catches all exceptions and logs them using the `logger` object, which is assumed to be defined in the scope of the `async_to_sync` method. This mechanism allows the application to handle errors gracefully and provide meaningful information for debugging purposes."
/home/r4ph/desenv/exception-miner-multi/projects/py/flask/tests/test_blueprints.py,test_add_template_filter,"def test_add_template_filter(app):
    bp = flask.Blueprint(""bp"", __name__)

    def my_reverse(s):
        return s[::-1]

    bp.add_app_template_filter(my_reverse)
    app.register_blueprint(bp, url_prefix=""/py"")
    assert ""my_reverse"" in app.jinja_env.filters.keys()
    assert app.jinja_env.filters[""my_reverse""] == my_reverse
    assert app.jinja_env.filters[""my_reverse""](""abcd"") == ""dcba""",,0,0,0,0,0,0,0,0,0,0,,,,0,0,0,,flask,"
Yes, this code needs an exception handling mechanism. The `my_reverse` function raises an error when passed an empty string as its input. The `assert` statements in the test function are not testing for this case and will fail if an empty string is passed to the filter.

Here's a corrected version of the code with exception handling added:
```python
def test_add_template_filter(app):
    bp = flask.Blueprint(""bp"", __name__)

    def my_reverse(s):
        if not s:
            raise ValueError(""String is empty"")
        return s[::-1]

    bp.add_app_template_filter(my_reverse)
    app.register_blueprint(bp, url_prefix=""/py"")
    assert ""my_reverse"" in app.jinja_env.filters.keys()
    try:
        assert app.jinja_env.filters[""my_reverse""](""abcd"") == ""dcba""
    except ValueError as e:
        print(e)
```"
/home/r4ph/desenv/exception-miner-multi/projects/py/flask/tests/test_blueprints.py,a,"def a():
        return "", "".join(flask.g.seen)",,0,0,0,0,0,0,0,0,0,0,,,,0,0,0,,flask,"
No, this code does not require an exception handling mechanism. The `return` statement is used to return a value from a function, and in this case, the value being returned is the result of the `join()` method called on the `flask.g.seen` variable. If `flask.g.seen` is not defined or does not exist, the code will raise a `NameError`.

However, if you want to handle any potential errors that may occur during the execution of this code, you can use an `try-except` block to catch any exceptions that are raised and handle them appropriately. For example:
```
def a():
    try:
        return "", "".join(flask.g.seen)
    except NameError:
        # Handle the exception here
        pass
```
In this case, if an error is raised during the execution of the `return` statement, the `except` block will be executed and any necessary error handling can be performed."
/home/r4ph/desenv/exception-miner-multi/projects/py/flask/tests/test_logging.py,reset_logging,"def reset_logging(pytestconfig):
    root_handlers = logging.root.handlers[:]
    logging.root.handlers = []
    root_level = logging.root.level

    logger = logging.getLogger(""flask_test"")
    logger.handlers = []
    logger.setLevel(logging.NOTSET)

    logging_plugin = pytestconfig.pluginmanager.unregister(name=""logging-plugin"")

    yield

    logging.root.handlers[:] = root_handlers
    logging.root.setLevel(root_level)

    logger.handlers = []
    logger.setLevel(logging.NOTSET)

    if logging_plugin:
        pytestconfig.pluginmanager.register(logging_plugin, ""logging-plugin"")",,0,0,0,0,0,0,0,0,0,0,,,,0,0,0,,flask,"
Yes, this code needs an exception handling mechanism because it is using the `yield` statement inside a function that may raise an exception. The `yield` statement is used to create an iterator object, but it can also be used to implement try-except blocks. If any exception is raised during the execution of the function, the `yield` statement will catch the exception and prevent it from propagating to the caller.

To ensure that the function handles exceptions properly, we should add a `try` block around the code that may raise an exception, and use a `except` block to handle any exceptions that are raised. This will allow the function to continue executing even if an exception is raised, while still allowing us to log any errors that occur during execution.

Here's an example of how we can modify the code to include exception handling:
```python
def reset_logging(pytestconfig):
    root_handlers = logging.root.handlers[:]
    logging.root.handlers = []
    root_level = logging.root.level

    logger = logging.getLogger(""flask_test"")
    logger.handlers = []
    logger.setLevel(logging.NOTSET)

    try:
        logging_plugin = pytestconfig.pluginmanager.unregister(name=""logging-plugin"")
    except Exception as e:
        print(""Error unregistering logging plugin:"", e)

    yield

    logging.root.handlers[:] = root_handlers
    logging.root.setLevel(root_level)

    logger.handlers = []
    logger.setLevel(logging.NOTSET)

    if logging_plugin:
        pytestconfig.pluginmanager.register(logging_plugin, ""logging-plugin"")
```
In this example, we've added a `try` block around the code that may raise an exception (`pytestconfig.pluginmanager.unregister()`), and used a `except` block to handle any exceptions that are raised. If an exception is raised during execution of the function, the `except` block will be executed, and we can log the error message using the `print()` function."
/home/r4ph/desenv/exception-miner-multi/projects/py/flask/tests/test_basic.py,teardown_request2,"def teardown_request2(exc):
        assert type(exc) is ZeroDivisionError
        called.append(True)
        # This raises a new error and blows away sys.exc_info(), so we can
        # test that all teardown_requests get passed the same original
        # exception.
        try:
            raise TypeError()
        except Exception:
            pass",,1,1,0,1,1,0,0,0,0,0,Exception,TypeError,pass,0,0,0,"def teardown_request2(exc):
        assert type(exc) is ZeroDivisionError
        called.append(True)
        # This raises a new error and blows away sys.exc_info(), so we can
        # test that all teardown_requests get passed the same original
        # exception.
        raise TypeError()",flask,"
Yes, this code needs an exception handling mechanism because it raises a new error `TypeError` in the teardown_request2 function when the `exc` parameter is of type `ZeroDivisionError`. This can cause issues if the `TypeError` is not handled properly, as it will replace the original `ZeroDivisionError` and potentially mask the root cause of the issue."
/home/r4ph/desenv/exception-miner-multi/projects/py/flask/tests/test_cli.py,create_app,"def create_app():
        return Flask(""flaskgroup"")",,0,0,0,0,0,0,0,0,0,0,,,,0,0,0,,flask,"
No, this code does not appear to require any exception handling mechanisms. It simply defines a function named `create_app` that returns a new instance of the Flask class with the name ""flaskgroup""."
/home/r4ph/desenv/exception-miner-multi/projects/py/flask/tests/test_helpers.py,test_streaming_with_context,"def test_streaming_with_context(self, app, client):
        @app.route(""/"")
        def index():
            def generate():
                yield ""Hello ""
                yield flask.request.args[""name""]
                yield ""!""

            return flask.Response(flask.stream_with_context(generate()))

        rv = client.get(""/?name=World"")
        assert rv.data == b""Hello World!""",,0,0,0,0,0,0,0,0,0,0,,,,0,0,0,,flask,"
Yes, this code needs an exception handling mechanism because it is using the `yield` keyword in the `generate()` function. If the `yield` keyword raises an exception, the `flask.stream_with_context()` function will not catch it and the application will crash. Therefore, it is important to add a try-except block around the `flask.stream_with_context()` call to handle any exceptions that may occur during streaming."
/home/r4ph/desenv/exception-miner-multi/projects/py/flask/tests/test_user_error_handler.py,bp_forbidden_handler,"def bp_forbidden_handler(e):
        assert isinstance(e, Forbidden)
        return ""bp-forbidden""",,0,0,0,0,0,0,0,0,0,0,,,,0,0,0,,flask,"
Yes, this code needs an exception handling mechanism. The function `bp_forbidden_handler` is defined to handle the `Forbidden` exception, but it does not actually do anything with the exception once it is caught. To be useful, it would need to perform some action in response to the exception, such as logging the error or returning a specific value."
/home/r4ph/desenv/exception-miner-multi/projects/py/flask/src/flask/cli.py,routes_command,"def routes_command(sort: str, all_methods: bool) -> None:
    """"""Show all registered routes with endpoints and methods.""""""
    rules = list(current_app.url_map.iter_rules())

    if not rules:
        click.echo(""No routes were registered."")
        return

    ignored_methods = set() if all_methods else {""HEAD"", ""OPTIONS""}
    host_matching = current_app.url_map.host_matching
    has_domain = any(rule.host if host_matching else rule.subdomain for rule in rules)
    rows = []

    for rule in rules:
        row = [
            rule.endpoint,
            "", "".join(sorted((rule.methods or set()) - ignored_methods)),
        ]

        if has_domain:
            row.append((rule.host if host_matching else rule.subdomain) or """")

        row.append(rule.rule)
        rows.append(row)

    headers = [""Endpoint"", ""Methods""]
    sorts = [""endpoint"", ""methods""]

    if has_domain:
        headers.append(""Host"" if host_matching else ""Subdomain"")
        sorts.append(""domain"")

    headers.append(""Rule"")
    sorts.append(""rule"")

    try:
        rows.sort(key=itemgetter(sorts.index(sort)))
    except ValueError:
        pass

    rows.insert(0, headers)
    widths = [max(len(row[i]) for row in rows) for i in range(len(headers))]
    rows.insert(1, [""-"" * w for w in widths])
    template = ""  "".join(f""{{{i}:<{w}}}"" for i, w in enumerate(widths))

    for row in rows:
        click.echo(template.format(*row))",,1,1,0,0,0,0,0,0,0,0,ValueError,,pass,0,0,0,"def routes_command(sort: str, all_methods: bool) -> None:
    """"""Show all registered routes with endpoints and methods.""""""
    rules = list(current_app.url_map.iter_rules())

    if not rules:
        click.echo(""No routes were registered."")
        return

    ignored_methods = set() if all_methods else {""HEAD"", ""OPTIONS""}
    host_matching = current_app.url_map.host_matching
    has_domain = any(rule.host if host_matching else rule.subdomain for rule in rules)
    rows = []

    for rule in rules:
        row = [
            rule.endpoint,
            "", "".join(sorted((rule.methods or set()) - ignored_methods)),
        ]

        if has_domain:
            row.append((rule.host if host_matching else rule.subdomain) or """")

        row.append(rule.rule)
        rows.append(row)

    headers = [""Endpoint"", ""Methods""]
    sorts = [""endpoint"", ""methods""]

    if has_domain:
        headers.append(""Host"" if host_matching else ""Subdomain"")
        sorts.append(""domain"")

    headers.append(""Rule"")
    sorts.append(""rule"")

    rows.sort(key=itemgetter(sorts.index(sort)))

    rows.insert(0, headers)
    widths = [max(len(row[i]) for row in rows) for i in range(len(headers))]
    rows.insert(1, [""-"" * w for w in widths])
    template = ""  "".join(f""{{{i}:<{w}}}"" for i, w in enumerate(widths))

    for row in rows:
        click.echo(template.format(*row))",flask,"
Yes, this code needs an exception handling mechanism. The `rules` list is being generated by calling `current_app.url_map.iter_rules()`, which may raise an exception if the current app has not been initialized properly. Additionally, the `rows` list is being generated by calling `click.echo()` on each row, which may also raise an exception if there are any issues with printing to the console.

To handle these exceptions, you can wrap the code in a try-except block and catch any errors that may occur. For example:
```python
try:
    rules = list(current_app.url_map.iter_rules())
    rows = []

    for rule in rules:
        row = [
            rule.endpoint,
            "", "".join(sorted((rule.methods or set()) - ignored_methods)),
        ]

        if has_domain:
            row.append((rule.host if host_matching else rule.subdomain) or """")

        row.append(rule.rule)
        rows.append(row)

    headers = [""Endpoint"", ""Methods""]
    sorts = [""endpoint"", ""methods""]

    if has_domain:
        headers.append(""Host"" if host_matching else ""Subdomain"")
        sorts.append(""domain"")

    headers.append(""Rule"")
    sorts.append(""rule"")

    rows.sort(key=itemgetter(sorts.index(sort)))

    rows.insert(0, headers)
    widths = [max(len(row[i]) for row in rows) for i in range(len(headers))]
    rows.insert(1, [""-"" * w for w in widths])
    template = ""  "".join(f""{{{i}:<{w}}}"" for i, w in enumerate(widths))

    for row in rows:
        click.echo(template.format(*row))
except Exception as e:
    # Handle the exception here
```"
/home/r4ph/desenv/exception-miner-multi/projects/py/flask/src/flask/config.py,from_pyfile,"def from_pyfile(
        self, filename: str | os.PathLike[str], silent: bool = False
    ) -> bool:
        """"""Updates the values in the config from a Python file.  This function
        behaves as if the file was imported as module with the
        :meth:`from_object` function.

        :param filename: the filename of the config.  This can either be an
                         absolute filename or a filename relative to the
                         root path.
        :param silent: set to ``True`` if you want silent failure for missing
                       files.
        :return: ``True`` if the file was loaded successfully.

        .. versionadded:: 0.7
           `silent` parameter.
        """"""
        filename = os.path.join(self.root_path, filename)
        d = types.ModuleType(""config"")
        d.__file__ = filename
        try:
            with open(filename, mode=""rb"") as config_file:
                exec(compile(config_file.read(), filename, ""exec""), d.__dict__)
        except OSError as e:
            if silent and e.errno in (errno.ENOENT, errno.EISDIR, errno.ENOTDIR):
                return False
            e.strerror = f""Unable to load configuration file ({e.strerror})""
            raise
        self.from_object(d)
        return True",,1,0,0,0,1,0,1,0,0,0,OSError,,"if silent and e.errno in (errno.ENOENT, errno.EISDIR, errno.ENOTDIR):
                return False
            e.strerror = f""Unable to load configuration file ({e.strerror})""
            raise",0,0,0,"def from_pyfile(
        self, filename: str | os.PathLike[str], silent: bool = False
    ) -> bool:
        """"""Updates the values in the config from a Python file.  This function
        behaves as if the file was imported as module with the
        :meth:`from_object` function.

        :param filename: the filename of the config.  This can either be an
                         absolute filename or a filename relative to the
                         root path.
        :param silent: set to ``True`` if you want silent failure for missing
                       files.
        :return: ``True`` if the file was loaded successfully.

        .. versionadded:: 0.7
           `silent` parameter.
        """"""
        filename = os.path.join(self.root_path, filename)
        d = types.ModuleType(""config"")
        d.__file__ = filename
        with open(filename, mode=""rb"") as config_file:
                exec(compile(config_file.read(), filename, ""exec""), d.__dict__)
        self.from_object(d)
        return True",flask,"
Yes, this code needs an exception handling mechanism to handle cases where the file specified by `filename` does not exist or is not readable. The `open()` function can raise various exceptions such as `FileNotFoundError`, `PermissionError`, and `OSError`. Therefore, it is important to include a try-except block to catch these exceptions and handle them appropriately."
/home/r4ph/desenv/exception-miner-multi/projects/py/flask/src/flask/templating.py,_get_source_explained,"def _get_source_explained(
        self, environment: BaseEnvironment, template: str
    ) -> tuple[str, str | None, t.Callable[[], bool] | None]:
        attempts = []
        rv: tuple[str, str | None, t.Callable[[], bool] | None] | None
        trv: None | (tuple[str, str | None, t.Callable[[], bool] | None]) = None

        for srcobj, loader in self._iter_loaders(template):
            try:
                rv = loader.get_source(environment, template)
                if trv is None:
                    trv = rv
            except TemplateNotFound:
                rv = None
            attempts.append((loader, srcobj, rv))

        from .debughelpers import explain_template_loading_attempts

        explain_template_loading_attempts(self.app, template, attempts)

        if trv is not None:
            return trv
        raise TemplateNotFound(template)",,1,0,0,0,1,0,0,0,0,0,TemplateNotFound,TemplateNotFound,rv = None,0,0,0,"def _get_source_explained(
        self, environment: BaseEnvironment, template: str
    ) -> tuple[str, str | None, t.Callable[[], bool] | None]:
        attempts = []
        rv: tuple[str, str | None, t.Callable[[], bool] | None] | None
        trv: None | (tuple[str, str | None, t.Callable[[], bool] | None]) = None

        for srcobj, loader in self._iter_loaders(template):
            rv = loader.get_source(environment, template)
                if trv is None:
                    trv = rv
            attempts.append((loader, srcobj, rv))

        from .debughelpers import explain_template_loading_attempts

        explain_template_loading_attempts(self.app, template, attempts)

        if trv is not None:
            return trv
        raise TemplateNotFound(template)",flask,"
Yes, the code snippet contains an exception handling mechanism in the form of the `TemplateNotFound` exception. If the `trv` variable is not set to a non-None value after iterating through the loaders and still being None at the end of the loop, then it will raise a `TemplateNotFound` exception with the message ""Template not found: <template_name>""."
/home/r4ph/desenv/exception-miner-multi/projects/py/flask/src/flask/helpers.py,stream_with_context,"def stream_with_context(
    generator_or_function: t.Iterator[t.AnyStr] | t.Callable[..., t.Iterator[t.AnyStr]],
) -> t.Iterator[t.AnyStr]:
    """"""Request contexts disappear when the response is started on the server.
    This is done for efficiency reasons and to make it less likely to encounter
    memory leaks with badly written WSGI middlewares.  The downside is that if
    you are using streamed responses, the generator cannot access request bound
    information any more.

    This function however can help you keep the context around for longer::

        from flask import stream_with_context, request, Response

        @app.route('/stream')
        def streamed_response():
            @stream_with_context
            def generate():
                yield 'Hello '
                yield request.args['name']
                yield '!'
            return Response(generate())

    Alternatively it can also be used around a specific generator::

        from flask import stream_with_context, request, Response

        @app.route('/stream')
        def streamed_response():
            def generate():
                yield 'Hello '
                yield request.args['name']
                yield '!'
            return Response(stream_with_context(generate()))

    .. versionadded:: 0.9
    """"""
    try:
        gen = iter(generator_or_function)  # type: ignore[arg-type]
    except TypeError:

        def decorator(*args: t.Any, **kwargs: t.Any) -> t.Any:
            gen = generator_or_function(*args, **kwargs)  # type: ignore[operator]
            return stream_with_context(gen)

        return update_wrapper(decorator, generator_or_function)  # type: ignore[arg-type, return-value]

    def generator() -> t.Iterator[t.AnyStr | None]:
        ctx = _cv_request.get(None)
        if ctx is None:
            raise RuntimeError(
                ""'stream_with_context' can only be used when a request""
                "" context is active, such as in a view function.""
            )
        with ctx:
            # Dummy sentinel.  Has to be inside the context block or we're
            # not actually keeping the context around.
            yield None

            # The try/finally is here so that if someone passes a WSGI level
            # iterator in we're still running the cleanup logic.  Generators
            # don't need that because they are closed on their destruction
            # automatically.
            try:
                yield from gen
            finally:
                if hasattr(gen, ""close""):
                    gen.close()

    # The trick is to start the generator.  Then the code execution runs until
    # the first dummy None is yielded at which point the context was already
    # pushed.  This item is discarded.  Then when the iteration continues the
    # real generator is executed.
    wrapped_g = generator()
    next(wrapped_g)
    return wrapped_g  # type: ignore[return-value]",,1,0,1,0,1,0,0,0,0,0,TypeError,RuntimeError,"def decorator(*args: t.Any, **kwargs: t.Any) -> t.Any:
            gen = generator_or_function(*args, **kwargs)  # type: ignore[operator]
            return stream_with_context(gen)

        return update_wrapper(decorator, generator_or_function)  # type: ignore[arg-type, return-value]",0,0,0,"def stream_with_context(
    generator_or_function: t.Iterator[t.AnyStr] | t.Callable[..., t.Iterator[t.AnyStr]],
) -> t.Iterator[t.AnyStr]:
    """"""Request contexts disappear when the response is started on the server.
    This is done for efficiency reasons and to make it less likely to encounter
    memory leaks with badly written WSGI middlewares.  The downside is that if
    you are using streamed responses, the generator cannot access request bound
    information any more.

    This function however can help you keep the context around for longer::

        from flask import stream_with_context, request, Response

        @app.route('/stream')
        def streamed_response():
            @stream_with_context
            def generate():
                yield 'Hello '
                yield request.args['name']
                yield '!'
            return Response(generate())

    Alternatively it can also be used around a specific generator::

        from flask import stream_with_context, request, Response

        @app.route('/stream')
        def streamed_response():
            def generate():
                yield 'Hello '
                yield request.args['name']
                yield '!'
            return Response(stream_with_context(generate()))

    .. versionadded:: 0.9
    """"""
    gen = iter(generator_or_function)  # type: ignore[arg-type]

    def generator() -> t.Iterator[t.AnyStr | None]:
        ctx = _cv_request.get(None)
        if ctx is None:
            raise RuntimeError(
                ""'stream_with_context' can only be used when a request""
                "" context is active, such as in a view function.""
            )
        with ctx:
            # Dummy sentinel.  Has to be inside the context block or we're
            # not actually keeping the context around.
            yield None

            # The try/finally is here so that if someone passes a WSGI level
            # iterator in we're still running the cleanup logic.  Generators
            # don't need that because they are closed on their destruction
            # automatically.
            try:
                yield from gen
            finally:
                if hasattr(gen, ""close""):
                    gen.close()

    # The trick is to start the generator.  Then the code execution runs until
    # the first dummy None is yielded at which point the context was already
    # pushed.  This item is discarded.  Then when the iteration continues the
    # real generator is executed.
    wrapped_g = generator()
    next(wrapped_g)
    return wrapped_g  # type: ignore[return-value]",flask,"
Yes, the code needs an exception handling mechanism. The `stream_with_context` function catches any exceptions raised by the passed generator and raises them again as a new exception, which is not ideal for production use. It's better to handle exceptions explicitly in the code and provide meaningful error messages to users. Additionally, the code may also benefit from logging the errors to a file or database for debugging purposes."
/home/r4ph/desenv/exception-miner-multi/projects/py/flask/src/flask/config.py,from_file,"def from_file(
        self,
        filename: str | os.PathLike[str],
        load: t.Callable[[t.IO[t.Any]], t.Mapping[str, t.Any]],
        silent: bool = False,
        text: bool = True,
    ) -> bool:
        """"""Update the values in the config from a file that is loaded
        using the ``load`` parameter. The loaded data is passed to the
        :meth:`from_mapping` method.

        .. code-block:: python

            import json
            app.config.from_file(""config.json"", load=json.load)

            import tomllib
            app.config.from_file(""config.toml"", load=tomllib.load, text=False)

        :param filename: The path to the data file. This can be an
            absolute path or relative to the config root path.
        :param load: A callable that takes a file handle and returns a
            mapping of loaded data from the file.
        :type load: ``Callable[[Reader], Mapping]`` where ``Reader``
            implements a ``read`` method.
        :param silent: Ignore the file if it doesn't exist.
        :param text: Open the file in text or binary mode.
        :return: ``True`` if the file was loaded successfully.

        .. versionchanged:: 2.3
            The ``text`` parameter was added.

        .. versionadded:: 2.0
        """"""
        filename = os.path.join(self.root_path, filename)

        try:
            with open(filename, ""r"" if text else ""rb"") as f:
                obj = load(f)
        except OSError as e:
            if silent and e.errno in (errno.ENOENT, errno.EISDIR):
                return False

            e.strerror = f""Unable to load configuration file ({e.strerror})""
            raise

        return self.from_mapping(obj)",,1,0,0,0,1,0,1,0,0,0,OSError,,"if silent and e.errno in (errno.ENOENT, errno.EISDIR):
                return False

            e.strerror = f""Unable to load configuration file ({e.strerror})""
            raise",0,0,0,"def from_file(
        self,
        filename: str | os.PathLike[str],
        load: t.Callable[[t.IO[t.Any]], t.Mapping[str, t.Any]],
        silent: bool = False,
        text: bool = True,
    ) -> bool:
        """"""Update the values in the config from a file that is loaded
        using the ``load`` parameter. The loaded data is passed to the
        :meth:`from_mapping` method.

        .. code-block:: python

            import json
            app.config.from_file(""config.json"", load=json.load)

            import tomllib
            app.config.from_file(""config.toml"", load=tomllib.load, text=False)

        :param filename: The path to the data file. This can be an
            absolute path or relative to the config root path.
        :param load: A callable that takes a file handle and returns a
            mapping of loaded data from the file.
        :type load: ``Callable[[Reader], Mapping]`` where ``Reader``
            implements a ``read`` method.
        :param silent: Ignore the file if it doesn't exist.
        :param text: Open the file in text or binary mode.
        :return: ``True`` if the file was loaded successfully.

        .. versionchanged:: 2.3
            The ``text`` parameter was added.

        .. versionadded:: 2.0
        """"""
        filename = os.path.join(self.root_path, filename)

        with open(filename, ""r"" if text else ""rb"") as f:
                obj = load(f)

        return self.from_mapping(obj)",flask,"
Yes, this code needs an exception handling mechanism. The `open()` function can raise a `FileNotFoundError` exception if the file does not exist, and the `load()` function can raise other exceptions depending on what it is doing. Therefore, it is important to catch any such exceptions and handle them appropriately."
/home/r4ph/desenv/exception-miner-multi/projects/py/flask/tests/test_appctx.py,test_app_tearing_down_with_previous_exception,"def test_app_tearing_down_with_previous_exception(app):
    cleanup_stuff = []

    @app.teardown_appcontext
    def cleanup(exception):
        cleanup_stuff.append(exception)

    try:
        raise Exception(""dummy"")
    except Exception:
        pass

    with app.app_context():
        pass

    assert cleanup_stuff == [None]",,1,1,0,1,1,1,0,0,0,0,Exception,Exception,pass,0,0,0,"def test_app_tearing_down_with_previous_exception(app):
    cleanup_stuff = []

    @app.teardown_appcontext
    def cleanup(exception):
        cleanup_stuff.append(exception)

    raise Exception(""dummy"")

    with app.app_context():
        pass

    assert cleanup_stuff == [None]",flask,"
Yes, the code needs an exception handling mechanism because it raises an Exception and then continues running without any checks for exceptions. The `cleanup` function is executed even when an exception is raised, which could cause issues if the cleanup code has side effects that need to be undone in case of an error. Additionally, the test does not assert whether an exception was raised or not, so it will always pass even if there were errors during the cleanup process. To fix this issue, the test should catch any exceptions raised by the `cleanup` function and assert that they are properly handled."
/home/r4ph/desenv/exception-miner-multi/projects/py/flask/src/flask/sansio/scaffold.py,_path_is_relative_to,"def _path_is_relative_to(path: pathlib.PurePath, base: str) -> bool:
    # Path.is_relative_to doesn't exist until Python 3.9
    try:
        path.relative_to(base)
        return True
    except ValueError:
        return False",,1,0,0,0,0,0,0,0,0,1,ValueError,,return False,0,0,0,"def _path_is_relative_to(path: pathlib.PurePath, base: str) -> bool:
    # Path.is_relative_to doesn't exist until Python 3.9
    path.relative_to(base)
        return True",flask,"
Yes, this code needs an exception handling mechanism because it uses the `Path.relative_to()` method, which may raise a `ValueError` if the `path` and `base` arguments are not compatible. Therefore, you should add a `try-except` block to handle any potential errors that may arise during the execution of this code."
